Workbook

Sheet All_Stats
A1: CID | B1: Month | C1: Status | D1: DPO ID | E1: Category | F1: Goal | G1: Delivered | H1: Accepted | I1: Rejected | J1: Returned | K1: Pending | L1: Pending QA | M1: Left | N1: Unallocated | O1: Left to generate | P1: Campaign Type
A2: DC58772 | B2: Overall | C2: Live | D2: T1 | E2: AG | F2: 5 | G2: 12 | H2: 0 | I2: 4 | J2: 1 | K2: 7 | L2: 4 | M2: 5 | P2: Appointment Setting
A3: DC30001 | B3: Overall | C3: Live | D3: Total | E3: AG | F3: 5 | G3: 12 | H3: 0 | I3: 4 | J3: 1 | K3: 7 | L3: 4 | M3: 5 | N3: 0 | O3: 5 | P3: Appointment Setting
A4: DC30002 | B4: 45294.292 | C4: Live | D4: T1 | E4: AG | G4: 0 | H4: 0 | I4: 0 | J4: 0 | K4: 0 | L4: 0 | P4: Appointment Setting
A5: DC30003 | B5: 45323.292 | C5: Live | D5: T1 | E5: AG | G5: 9 | H5: 0 | I5: 4 | J5: 1 | K5: 4 | L5: 1 | P5: Appointment Setting
A6: DC30004 | B6: Overall | C6: Live | D6: T1 | E6: US | F6: 20 | G6: 5 | H6: 0 | I6: 1 | J6: 0 | K6: 4 | L6: 0 | M6: 20 | P6: Appointment Setting
A7: DC30005 | B7: Overall | C7: Live | D7: Total | E7: US | F7: 20 | G7: 5 | H7: 0 | I7: 1 | J7: 0 | K7: 4 | L7: 0 | M7: 20 | N7: 0 | O7: 20 | P7: Appointment Setting
A8: DC30006 | B8: Overall | C8: Live | D8: V4 | E8: ANZ | F8: 4 | G8: 0 | H8: 0 | I8: 0 | J8: 0 | K8: 0 | L8: 0 | M8: 4 | P8: Appointment Setting
A9: DC30007 | B9: Overall | C9: Live | D9: V38 | E9: ANZ | F9: 4 | G9: 4 | H9: 0 | I9: 1 | J9: 3 | K9: 0 | L9: 0 | M9: 4 | P9: Appointment Setting
A10: DC30008 | B10: Overall | C10: Live | D10: T1 | E10: ANZ | F10: 4 | G10: 6 | H10: 0 | I10: 1 | J10: 4 | K10: 1 | L10: 0 | M10: 4 | P10: Appointment Setting
A11: DC30009 | B11: Overall | C11: Live | D11: Total | E11: ANZ | F11: 4 | G11: 10 | H11: 0 | I11: 2 | J11: 7 | K11: 1 | L11: 0 | M11: 4 | N11: -8 | O11: 4 | P11: Appointment Setting
A12: DC30010 | B12: 45171.292 | C12: Live | D12: V38 | E12: ANZ | G12: 2 | H12: 0 | I12: 0 | J12: 2 | K12: 0 | L12: 0 | P12: Appointment Setting
A13: DC30011 | B13: 45172.292 | C13: Live | D13: T1 | E13: ANZ | G13: 0 | H13: 0 | I13: 0 | J13: 0 | K13: 0 | L13: 0 | P13: Appointment Setting
A14: DC30012 | B14: 45201.292 | C14: Live | D14: V38 | E14: ANZ | G14: 1 | H14: 0 | I14: 1 | J14: 0 | K14: 0 | L14: 0 | P14: Appointment Setting
A15: DC30013 | B15: 45202.292 | C15: Live | D15: T1 | E15: ANZ | G15: 1 | H15: 0 | I15: 1 | J15: 0 | K15: 0 | L15: 0 | P15: Appointment Setting
A16: DC30014 | B16: 45232.25 | C16: Live | D16: V4 | E16: ANZ | G16: 0 | H16: 0 | I16: 0 | J16: 0 | K16: 0 | L16: 0 | P16: Appointment Setting
A17: DC30015 | B17: 45232.25 | C17: Live | D17: V38 | E17: ANZ | G17: 1 | H17: 0 | I17: 0 | J17: 1 | K17: 0 | L17: 0 | P17: Appointment Setting
A18: DC30016 | B18: 45233.25 | C18: Live | D18: T1 | E18: ANZ | G18: 0 | H18: 0 | I18: 0 | J18: 0 | K18: 0 | L18: 0 | P18: Appointment Setting
A19: DC30017 | B19: 45262.292 | C19: Live | D19: T1 | E19: ANZ | G19: 4 | H19: 0 | I19: 0 | J19: 4 | K19: 0 | L19: 0 | P19: Appointment Setting
A20: DC30018 | B20: 45293.292 | C20: Live | D20: T1 | E20: ANZ | G20: 0 | H20: 0 | I20: 0 | J20: 0 | K20: 0 | L20: 0 | P20: Appointment Setting
A21: DC30019 | B21: Overall | C21: Live | D21: T1 | E21: Southeast Asia | F21: 2 | G21: 8 | H21: 0 | I21: 3 | J21: 4 | K21: 1 | L21: 1 | M21: 2 | P21: Appointment Setting
A22: DC58772 | B22: Overall | C22: Live | D22: Total | E22: Southeast Asia | F22: 2 | G22: 8 | H22: 0 | I22: 3 | J22: 4 | K22: 1 | L22: 1 | M22: 2 | N22: 0 | O22: 2 | P22: Appointment Setting
A23: DC30020 | B23: 45262.292 | C23: Live | D23: T1 | E23: Southeast Asia | G23: 6 | H23: 0 | I23: 2 | J23: 4 | K23: 0 | L23: 0 | P23: Appointment Setting
A24: DC30021 | B24: 45294.292 | C24: Live | D24: T1 | E24: Southeast Asia | G24: 0 | H24: 0 | I24: 0 | J24: 0 | K24: 0 | L24: 0 | P24: Appointment Setting
A25: DC30022 | B25: Overall | C25: Live | D25: T1 | E25: APAC | F25: 3 | G25: 6 | H25: 0 | I25: 4 | J25: 0 | K25: 2 | L25: 0 | M25: 3 | P25: Appointment Setting
A26: DC30023 | B26: Overall | C26: Live | D26: Total | E26: APAC | F26: 3 | G26: 6 | H26: 0 | I26: 4 | J26: 0 | K26: 2 | L26: 0 | M26: 3 | N26: 0 | O26: 3 | P26: Appointment Setting
A27: DC30024 | B27: 45294.292 | C27: Live | D27: T1 | E27: APAC | G27: 0 | H27: 0 | I27: 0 | J27: 0 | K27: 0 | L27: 0 | P27: Appointment Setting
A28: DC30025 | B28: Overall | C28: Live | D28: T1 | E28: ANZ | F28: 2 | G28: 1 | H28: 0 | I28: 1 | J28: 0 | K28: 0 | L28: 0 | M28: 2 | P28: Appointment Setting
A29: DC30026 | B29: Overall | C29: Live | D29: Total | E29: ANZ | F29: 2 | G29: 1 | H29: 0 | I29: 1 | J29: 0 | K29: 0 | L29: 0 | M29: 2 | N29: 0 | O29: 2 | P29: Appointment Setting
A30: DC30027 | B30: 45293.292 | C30: Live | D30: T1 | E30: ANZ | G30: 1 | H30: 0 | I30: 1 | J30: 0 | K30: 0 | L30: 0 | P30: Appointment Setting
A31: DC30028 | B31: Overall | C31: Closed | D31: V38 | E31: ASEAN | F31: 1 | G31: 6 | H31: 2 | I31: 1 | J31: 3 | K31: 0 | L31: 0 | M31: -1 | P31: Appointment Setting
A32: DC30029 | B32: Overall | C32: Live | D32: T1 | E32: ASEAN | F32: 3 | G32: 19 | H32: 1 | I32: 7 | J32: 6 | K32: 5 | L32: 0 | M32: 2 | P32: Appointment Setting
A33: DC30030 | B33: Overall | C33: Live | D33: Total | E33: ASEAN | F33: 4 | G33: 25 | H33: 3 | I33: 8 | J33: 9 | K33: 5 | L33: 0 | M33: 1 | N33: 0 | O33: -2 | P33: Appointment Setting
A34: DC30031 | B34: 45171.292 | C34: Live | D34: V38 | E34: ASEAN | G34: 2 | H34: 1 | I34: 0 | J34: 1 | K34: 0 | L34: 0 | P34: Appointment Setting
A35: DC30032 | B35: 45202.292 | C35: Live | D35: V38 | E35: ASEAN | G35: 4 | H35: 1 | I35: 1 | J35: 2 | K35: 0 | L35: 0 | P35: Appointment Setting
A36: DC30033 | B36: 45203.292 | C36: Live | D36: T1 | E36: ASEAN | G36: 0 | H36: 0 | I36: 0 | J36: 0 | K36: 0 | L36: 0 | P36: Appointment Setting
A37: DC30034 | B37: 45264.292 | C37: Live | D37: T1 | E37: ASEAN | G37: 7 | H37: 0 | I37: 2 | J37: 5 | K37: 0 | L37: 0 | P37: Appointment Setting
A38: DC30035 | B38: 45293.292 | C38: Live | D38: T1 | E38: ASEAN | G38: 7 | H38: 1 | I38: 4 | J38: 1 | K38: 1 | L38: 0 | P38: Appointment Setting
A39: DC30036 | B39: Overall | C39: Live | D39: T1 | E39: US | F39: 49 | G39: 58 | H39: 39 | I39: 9 | J39: 0 | K39: 10 | L39: 0 | M39: 10 | P39: MQL
A40: DC30037 | B40: Overall | C40: Closed | D40: T2 | E40: US | F40: 29 | G40: 35 | H40: 29 | I40: 5 | J40: 1 | K40: 0 | L40: 0 | M40: 0 | P40: MQL
...

Sheet Campaign Stats
A1: Current Volume Status
A2: Campaign Type | B2: N - LIVE | C2: N - Paused | D2: Goal - LIVE | E2: Accepted - LIVE | F2: Left | G2: Returns | H2: Pending - LIVE | I2: Pending - Paused
A3: Email Marketing | B3: =COUNTIFS('Campaign Tracking'!T:T,A3,'Campaign Tracking'!K:K,"live") -> 1 | C3: =COUNTIFS('Campaign Tracking'!T:T,A3,'Campaign Tracking'!K:K,"paused") -> 0 | D3: =SUMifs('Campaign Tracking'!D:D,'Campaign Tracking'!T:T,A3,'Campaign Tracking'!K:K,"LIVE") -> 183 | E3: =SUMIFS('Campaign Tracking'!F:F,'Campaign Tracking'!T:T,A3,'Campaign Tracking'!K:K,"LIVE") -> 57 | F3: =D3-E3 -> 126 | H3: =SUMIFS('Campaign Tracking'!H:H,'Campaign Tracking'!T:T,A3,'Campaign Tracking'!K:K,"LIVE") -> 107 | I3: =SUMIFS('Campaign Tracking'!H:H,'Campaign Tracking'!T:T,A3,'Campaign Tracking'!K:K,"PAUSED") -> 0
A4: LIVE EVENT | B4: =COUNTIFS('Campaign Tracking'!T:T,A4,'Campaign Tracking'!K:K,"live") -> 0 | C4: =COUNTIFS('Campaign Tracking'!T:T,A4,'Campaign Tracking'!K:K,"paused") -> 0 | D4: =SUMifs('Campaign Tracking'!D:D,'Campaign Tracking'!T:T,A4,'Campaign Tracking'!K:K,"LIVE") -> 0 | E4: =SUMIFS('Campaign Tracking'!F:F,'Campaign Tracking'!T:T,A4,'Campaign Tracking'!K:K,"LIVE") -> 0 | F4: =D4-E4 -> 0 | H4: =SUMIFS('Campaign Tracking'!H:H,'Campaign Tracking'!T:T,A4,'Campaign Tracking'!K:K,"LIVE") -> 0 | I4: =SUMIFS('Campaign Tracking'!H:H,'Campaign Tracking'!T:T,A4,'Campaign Tracking'!K:K,"PAUSED") -> 0
A5: Webinar | B5: =COUNTIFS('Campaign Tracking'!T:T,A5,'Campaign Tracking'!K:K,"live") -> 0 | C5: =COUNTIFS('Campaign Tracking'!T:T,A5,'Campaign Tracking'!K:K,"paused") -> 0 | D5: =SUMifs('Campaign Tracking'!D:D,'Campaign Tracking'!T:T,A5,'Campaign Tracking'!K:K,"LIVE") -> 0 | E5: =SUMIFS('Campaign Tracking'!F:F,'Campaign Tracking'!T:T,A5,'Campaign Tracking'!K:K,"LIVE") -> 0 | F5: =D5-E5 -> 0 | H5: =SUMIFS('Campaign Tracking'!H:H,'Campaign Tracking'!T:T,A5,'Campaign Tracking'!K:K,"LIVE") -> 0 | I5: =SUMIFS('Campaign Tracking'!H:H,'Campaign Tracking'!T:T,A5,'Campaign Tracking'!K:K,"PAUSED") -> 0
A6: Survey | B6: =COUNTIFS('Campaign Tracking'!T:T,A6,'Campaign Tracking'!K:K,"live") -> 0 | C6: =COUNTIFS('Campaign Tracking'!T:T,A6,'Campaign Tracking'!K:K,"paused") -> 0 | D6: =SUMifs('Campaign Tracking'!D:D,'Campaign Tracking'!T:T,A6,'Campaign Tracking'!K:K,"LIVE") -> 0 | E6: =SUMIFS('Campaign Tracking'!F:F,'Campaign Tracking'!T:T,A6,'Campaign Tracking'!K:K,"LIVE") -> 0 | F6: =D6-E6 -> 0 | H6: =SUMIFS('Campaign Tracking'!H:H,'Campaign Tracking'!T:T,A6,'Campaign Tracking'!K:K,"LIVE") -> 0 | I6: =SUMIFS('Campaign Tracking'!H:H,'Campaign Tracking'!T:T,A6,'Campaign Tracking'!K:K,"PAUSED") -> 0
A7: MQL | B7: =COUNTIFS('Campaign Tracking'!T:T,A7,'Campaign Tracking'!K:K,"live") -> 1 | C7: =COUNTIFS('Campaign Tracking'!T:T,A7,'Campaign Tracking'!K:K,"paused") -> 0 | D7: =SUMifs('Campaign Tracking'!D:D,'Campaign Tracking'!T:T,A7,'Campaign Tracking'!K:K,"LIVE") -> 106 | E7: =SUMIFS('Campaign Tracking'!F:F,'Campaign Tracking'!T:T,A7,'Campaign Tracking'!K:K,"LIVE") -> 12 | F7: =D7-E7 -> 94 | H7: =SUMIFS('Campaign Tracking'!H:H,'Campaign Tracking'!T:T,A7,'Campaign Tracking'!K:K,"LIVE") -> 17 | I7: =SUMIFS('Campaign Tracking'!H:H,'Campaign Tracking'!T:T,A7,'Campaign Tracking'!K:K,"PAUSED") -> 0
A8: SQL | B8: =COUNTIFS('Campaign Tracking'!T:T,A8,'Campaign Tracking'!K:K,"live") -> 0 | C8: =COUNTIFS('Campaign Tracking'!T:T,A8,'Campaign Tracking'!K:K,"paused") -> 0 | D8: =SUMifs('Campaign Tracking'!D:D,'Campaign Tracking'!T:T,A8,'Campaign Tracking'!K:K,"LIVE") -> 0 | E8: =SUMIFS('Campaign Tracking'!F:F,'Campaign Tracking'!T:T,A8,'Campaign Tracking'!K:K,"LIVE") -> 0 | F8: =D8-E8 -> 0 | H8: =SUMIFS('Campaign Tracking'!H:H,'Campaign Tracking'!T:T,A8,'Campaign Tracking'!K:K,"LIVE") -> 0 | I8: =SUMIFS('Campaign Tracking'!H:H,'Campaign Tracking'!T:T,A8,'Campaign Tracking'!K:K,"PAUSED") -> 0
A9: Custom questions | B9: =COUNTIFS('Campaign Tracking'!T:T,A9,'Campaign Tracking'!K:K,"live") -> 1 | C9: =COUNTIFS('Campaign Tracking'!T:T,A9,'Campaign Tracking'!K:K,"paused") -> 0 | D9: =SUMifs('Campaign Tracking'!D:D,'Campaign Tracking'!T:T,A9,'Campaign Tracking'!K:K,"LIVE") -> 125 | E9: =SUMIFS('Campaign Tracking'!F:F,'Campaign Tracking'!T:T,A9,'Campaign Tracking'!K:K,"LIVE") -> 12 | F9: =D9-E9 -> 113 | H9: =SUMIFS('Campaign Tracking'!H:H,'Campaign Tracking'!T:T,A9,'Campaign Tracking'!K:K,"LIVE") -> 43 | I9: =SUMIFS('Campaign Tracking'!H:H,'Campaign Tracking'!T:T,A9,'Campaign Tracking'!K:K,"PAUSED") -> 0
A10: Soft BANT | B10: =COUNTIFS('Campaign Tracking'!T:T,A10,'Campaign Tracking'!K:K,"live") -> 0 | C10: =COUNTIFS('Campaign Tracking'!T:T,A10,'Campaign Tracking'!K:K,"paused") -> 0 | D10: =SUMifs('Campaign Tracking'!D:D,'Campaign Tracking'!T:T,A10,'Campaign Tracking'!K:K,"LIVE") -> 0 | E10: =SUMIFS('Campaign Tracking'!F:F,'Campaign Tracking'!T:T,A10,'Campaign Tracking'!K:K,"LIVE") -> 0 | F10: =D10-E10 -> 0 | H10: =SUMIFS('Campaign Tracking'!H:H,'Campaign Tracking'!T:T,A10,'Campaign Tracking'!K:K,"LIVE") -> 0 | I10: =SUMIFS('Campaign Tracking'!H:H,'Campaign Tracking'!T:T,A10,'Campaign Tracking'!K:K,"PAUSED") -> 0
A11: BANT | B11: =COUNTIFS('Campaign Tracking'!T:T,A11,'Campaign Tracking'!K:K,"live") -> 0 | C11: =COUNTIFS('Campaign Tracking'!T:T,A11,'Campaign Tracking'!K:K,"paused") -> 0 | D11: =SUMifs('Campaign Tracking'!D:D,'Campaign Tracking'!T:T,A11,'Campaign Tracking'!K:K,"LIVE") -> 0 | E11: =SUMIFS('Campaign Tracking'!F:F,'Campaign Tracking'!T:T,A11,'Campaign Tracking'!K:K,"LIVE") -> 0 | F11: =D11-E11 -> 0 | H11: =SUMIFS('Campaign Tracking'!H:H,'Campaign Tracking'!T:T,A11,'Campaign Tracking'!K:K,"LIVE") -> 0 | I11: =SUMIFS('Campaign Tracking'!H:H,'Campaign Tracking'!T:T,A11,'Campaign Tracking'!K:K,"PAUSED") -> 0
A12: CALL Back | B12: =COUNTIFS('Campaign Tracking'!T:T,A12,'Campaign Tracking'!K:K,"live") -> 1 | C12: =COUNTIFS('Campaign Tracking'!T:T,A12,'Campaign Tracking'!K:K,"paused") -> 0 | D12: =SUMifs('Campaign Tracking'!D:D,'Campaign Tracking'!T:T,A12,'Campaign Tracking'!K:K,"LIVE") -> 20 | E12: =SUMIFS('Campaign Tracking'!F:F,'Campaign Tracking'!T:T,A12,'Campaign Tracking'!K:K,"LIVE") -> 15 | F12: =D12-E12 -> 5 | H12: =SUMIFS('Campaign Tracking'!H:H,'Campaign Tracking'!T:T,A12,'Campaign Tracking'!K:K,"LIVE") -> 0 | I12: =SUMIFS('Campaign Tracking'!H:H,'Campaign Tracking'!T:T,A12,'Campaign Tracking'!K:K,"PAUSED") -> 0
A13: Appointment Setting | B13: =COUNTIFS('Campaign Tracking'!T:T,A13,'Campaign Tracking'!K:K,"live") -> 1 | C13: =COUNTIFS('Campaign Tracking'!T:T,A13,'Campaign Tracking'!K:K,"paused") -> 0 | D13: =SUMifs('Campaign Tracking'!D:D,'Campaign Tracking'!T:T,A13,'Campaign Tracking'!K:K,"LIVE") -> 5000 | E13: =SUMIFS('Campaign Tracking'!F:F,'Campaign Tracking'!T:T,A13,'Campaign Tracking'!K:K,"LIVE") -> 1651 | F13: =D13-E13 -> 3349 | H13: =SUMIFS('Campaign Tracking'!H:H,'Campaign Tracking'!T:T,A13,'Campaign Tracking'!K:K,"LIVE") -> 75 | I13: =SUMIFS('Campaign Tracking'!H:H,'Campaign Tracking'!T:T,A13,'Campaign Tracking'!K:K,"PAUSED") -> 0
A14: Total | B14: =sum(B3:B13) -> 5 | C14: =sum(C3:C13) -> 0 | D14: =sum(D3:D13) -> 5434 | E14: =sum(E3:E13) -> 1747 | F14: =sum(F3:F13) -> 3687 | H14: =sum(H3:H13) -> 242 | I14: =sum(I3:I13) -> 0
A16: Monthly Progress - EM & DPO
A17: Month | B17: Delivered | C17: Rejected | D17: Rejection Rate | E17: Accepted | F17: Pending | G17: Returns | H17: N Campaigns | I17: N Vendors
A18: 44013 | B18: 1088 | C18: =B18-E18-F18 -> 386 | D18: =(C18/B18)*100% -> 0.35477941 | E18: 702 | F18: 0 | H18: 29 | I18: 14
A19: 44044 | B19: 903 | C19: =B19-E19-F19 -> 347 | D19: =(C19/B19)*100% -> 0.38427464 | E19: 556 | F19: 0 | H19: 27 | I19: 11
A20: 44075 | B20: 1811 | C20: =B20-E20-F20 -> 719 | D20: =(C20/B20)*100% -> 0.39701822 | E20: 1092 | F20: 0 | H20: 30 | I20: 8
A21: 44105 | B21: 2478 | C21: =B21-E21-F21 -> 722.6 | D21: =(C21/B21)*100% -> 0.29160613 | E21: 1755.4 | F21: 0 | H21: 30 | I21: 7
A22: 44136 | B22: 2285 | C22: =B22-E22-F22 -> 656 | D22: =(C22/B22)*100% -> 0.28708972 | E22: 1629 | F22: 0 | H22: 37 | I22: 7
A23: 44166 | B23: 1349 | C23: =B23-E23-F23 -> 421 | D23: =(C23/B23)*100% -> 0.31208302 | E23: 928 | F23: 0 | H23: 24 | I23: 5
A24: 44197 | B24: 1706 | C24: 471 | D24: =(C24/B24)*100% -> 0.27608441 | E24: 1235 | F24: 0 | H24: 39 | I24: 10
A25: 44228 | B25: 3534 | C25: 997 | D25: =(C25/B25)*100% -> 0.28211658 | E25: 2537 | F25: 0 | H25: 65 | I25: 18
A26: 44256 | B26: 4748 | C26: 1527 | D26: =(C26/B26)*100% -> 0.3216091 | E26: 3221 | F26: 0 | H26: 88 | I26: 19
A27: 44287 | B27: 6190 | C27: 2331 | D27: =(C27/B27)*100% -> 0.37657512 | E27: 3859 | F27: 0 | H27: 95 | I27: 17
A28: 44317 | B28: 5277 | C28: 2104 | D28: =(C28/B28)*100% -> 0.39871139 | E28: 3173 | F28: 0 | H28: 80 | I28: 24
A29: 44348 | B29: 5072 | C29: 2020 | D29: =(C29/B29)*100% -> 0.39826498 | E29: 3052 | F29: 0 | H29: 56 | I29: 20
A30: 44378 | B30: 6130 | C30: 2290 | D30: =(C30/B30)*100% -> 0.37357259 | E30: 3840 | F30: 0 | H30: 74 | I30: 14
A31: 44409 | B31: 7644 | C31: 3133 | D31: =(C31/B31)*100% -> 0.40986395 | E31: 4511 | F31: 0 | H31: 83 | I31: 16
A32: 44440 | B32: 4784 | C32: 2157 | D32: =(C32/B32)*100% -> 0.45087793 | E32: 2627 | F32: 0 | H32: 53 | I32: 16
A33: 44470 | B33: 3986 | C33: 1510 | D33: =(C33/B33)*100% -> 0.37882589 | E33: 2476 | F33: 0 | H33: 67 | I33: 17
A34: 44501 | B34: 5063 | C34: 2298 | D34: =(C34/B34)*100% -> 0.4538811 | E34: 2765 | F34: 0 | H34: 69 | I34: 19
A35: 44531 | B35: 3557 | C35: 1590 | D35: =(C35/B35)*100% -> 0.4470059 | E35: 1967 | F35: 0 | H35: 61 | I35: 18
... A53: 45078 | B53: 10063 | C53: 4291 | D53: =(C53/B53)*100% -> 0.42641359 | E53: 5711 | F53: 0 | H53: 120 | I53: 11
A54: 45108 | B54: 5127 | C54: 1843 | D54: =(C54/B54)*100% -> 0.35946948 | E54: 3197 | F54: 56 | G54: 31 | H54: 88 | I54: 10
A55: 45139 | B55: 7709 | C55: 3603 | D55: =(C55/B55)*100% -> 0.46737579 | E55: 3969 | F55: 0 | H55: 157 | I55: 10
A56: 45170 | B56: 7518 | C56: 2652 | D56: =(C56/B56)*100% -> 0.35275339 | E56: 4708 | F56: 102 | H56: 174 | I56: 10
A57: 45200 | B57: 6656 | C57: 2687 | D57: =(C57/B57)*100% -> 0.40369591 | E57: 3917 | F57: 21 | H57: 163 | I57: 10
A58: 45231 | B58: 8742 | C58: 3731 | D58: =(C58/B58)*100% -> 0.42679021 | E58: 4991 | F58: 6 | H58: 178 | I58: 12
...

Sheet Montly Stats
C2: Email marketing
A3: Month | B3: Vendor ID | C3: Vendor Name | D3: Delivered | E3: Rejected | F3: Rejection Rate | G3: Accepted | H3: Pending | I3: N Unique CIDS
A4: 45352 | B4: V36 | C4: Coleda | D4: =SUMIFS(All_Stats!$G:$G, All_Stats!$D:$D,$B4, All_Stats!$B:$B,">="&EOMONTH($A4,-1)+1, All_Stats!$B:$B,"<"&EOMONTH($A4,0)+1, All_Stats!$P:$P,"Email Marketing" ) -> 935 | E4: =SUMIFS(All_Stats!$I:$I, All_Stats!$D:$D,$B4, All_Stats!$B:$B,">="&EOMONTH($A4,-1)+1, All_Stats!$B:$B,"<"&EOMONTH($A4,0)+1, All_Stats!$P:$P,"Email Marketing" ) -> 117 | F4: =iferror(E4/D4,"N/A") -> 0.12513369 | G4: =SUMIFS(All_Stats!$H:$H, All_Stats!$D:$D,$B4, All_Stats!$B:$B,">="&EOMONTH($A4,-1)+1, All_Stats!$B:$B,"<"&EOMONTH($A4,0)+1, All_Stats!$P:$P,"Email Marketing" ) -> 130 | H4: =SUMIFS(All_Stats!$K:$K, All_Stats!$D:$D,$B4, All_Stats!$B:$B,">="&EOMONTH($A4,-1)+1, All_Stats!$B:$B,"<"&EOMONTH($A4,0)+1, All_Stats!$P:$P,"Email Marketing" ) -> 688 | I4: =IFERROR(__xludf.DUMMYFUNCTION("COUNTUNIQUEIFS(All_Stats!A:A, All_Stats!$D:$D,$B4, All_Stats!$B:$B,"">=""&EOMONTH($A4,-1)+1, All_Stats!$B:$B,""<""&EOMONTH($A4,0)+1, All_Stats!$P:$P,""Email Marketing"" )"),18.0) -> 18
A5: 45352 | B5: V5 | C5: =if(ifna(VLOOKUP(B5,'Vendor Directory'!A:C,3,0),"NOT FOUND")="","NOT FOUND",VLOOKUP(B5,'Vendor Directory'!A:C,3,0)) -> #N/A | D5: =SUMIFS(All_Stats!$G:$G, All_Stats!$D:$D,$B5, All_Stats!$B:$B,">="&EOMONTH($A5,-1)+1, All_Stats!$B:$B,"<"&EOMONTH($A5,0)+1, All_Stats!$P:$P,"Email Marketing" ) -> 876 | E5: =SUMIFS(All_Stats!$I:$I, All_Stats!$D:$D,$B5, All_Stats!$B:$B,">="&EOMONTH($A5,-1)+1, All_Stats!$B:$B,"<"&EOMONTH($A5,0)+1, All_Stats!$P:$P,"Email Marketing" ) -> 151 | F5: =iferror(E5/D5,"N/A") -> 0.17237443 | G5: =SUMIFS(All_Stats!$H:$H, All_Stats!$D:$D,$B5, All_Stats!$B:$B,">="&EOMONTH($A5,-1)+1, All_Stats!$B:$B,"<"&EOMONTH($A5,0)+1, All_Stats!$P:$P,"Email Marketing" ) -> 97 | H5: =SUMIFS(All_Stats!$K:$K, All_Stats!$D:$D,$B5, All_Stats!$B:$B,">="&EOMONTH($A5,-1)+1, All_Stats!$B:$B,"<"&EOMONTH($A5,0)+1, All_Stats!$P:$P,"Email Marketing" ) -> 628 | I5: =IFERROR(__xludf.DUMMYFUNCTION("COUNTUNIQUEIFS(All_Stats!A:A, All_Stats!$D:$D,$B5, All_Stats!$B:$B,"">=""&EOMONTH($A5,-1)+1, All_Stats!$B:$B,""<""&EOMONTH($A5,0)+1, All_Stats!$P:$P,""Email Marketing"" )"),27.0) -> 27
C6: Total | D6: =SUM(D4:D5) -> 1811 | E6: =SUM(E4:E5) -> 268 | F6: =iferror(E6/D6,"N/A") -> 0.14798454 | G6: =SUM(G4:G5) -> 227 | H6: =SUM(H4:H5) -> 1316
A8: Month | B8: Vendor ID | C8: Vendor Name | D8: Delivered | E8: Rejected | F8: Rejection Rate | G8: Accepted | H8: Pending | I8: N Unique CIDS
A9: 45352 | B9: T1 | C9: APAC TEAM | D9: =SUMIFS(All_Stats!$G:$G, All_Stats!$D:$D,$B9, All_Stats!$B:$B,">="&EOMONTH($A9,-1)+1, All_Stats!$B:$B,"<"&EOMONTH($A9,0)+1, All_Stats!$P:$P,"<>Email Marketing" ) -> 85 | E9: =SUMIFS(All_Stats!$I:$I, All_Stats!$D:$D,$B9, All_Stats!$B:$B,">="&EOMONTH($A9,-1)+1, All_Stats!$B:$B,"<"&EOMONTH($A9,0)+1, All_Stats!$P:$P,"<>Email Marketing" ) -> 19 | F9: =iferror(E9/D9,"N/A") -> 0.22352941 | G9: =SUMIFS(All_Stats!$H:$H, All_Stats!$D:$D,$B9, All_Stats!$B:$B,">="&EOMONTH($A9,-1)+1, All_Stats!$B:$B,"<"&EOMONTH($A9,0)+1, All_Stats!$P:$P,"<>Email Marketing" ) -> 17 | H9: =SUMIFS(All_Stats!$K:$K, All_Stats!$D:$D,$B9, All_Stats!$B:$B,">="&EOMONTH($A9,-1)+1, All_Stats!$B:$B,"<"&EOMONTH($A9,0)+1, All_Stats!$P:$P,"<>Email Marketing" ) -> 49 | I9: =IFERROR(__xludf.DUMMYFUNCTION("COUNTUNIQUEIFS(All_Stats!A:A, All_Stats!$D:$D,$B9, All_Stats!$B:$B,"">=""&EOMONTH($A9,-1)+1, All_Stats!$B:$B,""<""&EOMONTH($A9,0)+1, All_Stats!$P:$P,""<>Email Marketing"" )"),34.0) -> 34
A10: 45352 | B10: V2 | C10: =if(ifna(VLOOKUP(B10,'Vendor Directory'!A:C,3,0),"NOT FOUND")="","NOT FOUND",VLOOKUP(B10,'Vendor Directory'!A:C,3,0)) -> #N/A | D10: =SUMIFS(All_Stats!$G:$G, All_Stats!$D:$D,$B10, All_Stats!$B:$B,">="&EOMONTH($A10,-1)+1, All_Stats!$B:$B,"<"&EOMONTH($A10,0)+1, All_Stats!$P:$P,"<>Email Marketing" ) -> 63 | E10: =SUMIFS(All_Stats!$I:$I, All_Stats!$D:$D,$B10, All_Stats!$B:$B,">="&EOMONTH($A10,-1)+1, All_Stats!$B:$B,"<"&EOMONTH($A10,0)+1, All_Stats!$P:$P,"<>Email Marketing" ) -> 9 | F10: =iferror(E10/D10,"N/A") -> 0.14285714 | G10: =SUMIFS(All_Stats!$H:$H, All_Stats!$D:$D,$B10, All_Stats!$B:$B,">="&EOMONTH($A10,-1)+1, All_Stats!$B:$B,"<"&EOMONTH($A10,0)+1, All_Stats!$P:$P,"<>Email Marketing" ) -> 54 | H10: =SUMIFS(All_Stats!$K:$K, All_Stats!$D:$D,$B10, All_Stats!$B:$B,">="&EOMONTH($A10,-1)+1, All_Stats!$B:$B,"<"&EOMONTH($A10,0)+1, All_Stats!$P:$P,"<>Email Marketing" ) -> 0 | I10: =IFERROR(__xludf.DUMMYFUNCTION("COUNTUNIQUEIFS(All_Stats!A:A, All_Stats!$D:$D,$B10, All_Stats!$B:$B,"">=""&EOMONTH($A10,-1)+1, All_Stats!$B:$B,""<""&EOMONTH($A10,0)+1, All_Stats!$P:$P,""<>Email Marketing"" )"),10.0) -> 10
A11: 45352 | B11: V3 | C11: =if(ifna(VLOOKUP(B11,'Vendor Directory'!A:C,3,0),"NOT FOUND")="","NOT FOUND",VLOOKUP(B11,'Vendor Directory'!A:C,3,0)) -> #N/A | D11: =SUMIFS(All_Stats!$G:$G, All_Stats!$D:$D,$B11, All_Stats!$B:$B,">="&EOMONTH($A11,-1)+1, All_Stats!$B:$B,"<"&EOMONTH($A11,0)+1, All_Stats!$P:$P,"<>Email Marketing" ) -> 68 | E11: =SUMIFS(All_Stats!$I:$I, All_Stats!$D:$D,$B11, All_Stats!$B:$B,">="&EOMONTH($A11,-1)+1, All_Stats!$B:$B,"<"&EOMONTH($A11,0)+1, All_Stats!$P:$P,"<>Email Marketing" ) -> 21 | F11: =iferror(E11/D11,"N/A") -> 0.30882353 | G11: =SUMIFS(All_Stats!$H:$H, All_Stats!$D:$D,$B11, All_Stats!$B:$B,">="&EOMONTH($A11,-1)+1, All_Stats!$B:$B,"<"&EOMONTH($A11,0)+1, All_Stats!$P:$P,"<>Email Marketing" ) -> 0 | H11: =SUMIFS(All_Stats!$K:$K, All_Stats!$D:$D,$B11, All_Stats!$B:$B,">="&EOMONTH($A11,-1)+1, All_Stats!$B:$B,"<"&EOMONTH($A11,0)+1, All_Stats!$P:$P,"<>Email Marketing" ) -> 47 | I11: =IFERROR(__xludf.DUMMYFUNCTION("COUNTUNIQUEIFS(All_Stats!A:A, All_Stats!$D:$D,$B11, All_Stats!$B:$B,"">=""&EOMONTH($A11,-1)+1, All_Stats!$B:$B,""<""&EOMONTH($A11,0)+1, All_Stats!$P:$P,""<>Email Marketing"" )"),3.0) -> 3
A12: 45352 | B12: V20 | C12: =if(ifna(VLOOKUP(B12,'Vendor Directory'!A:C,3,0),"NOT FOUND")="","NOT FOUND",VLOOKUP(B12,'Vendor Directory'!A:C,3,0)) -> #N/A | D12: =SUMIFS(All_Stats!$G:$G, All_Stats!$D:$D,$B12, All_Stats!$B:$B,">="&EOMONTH($A12,-1)+1, All_Stats!$B:$B,"<"&EOMONTH($A12,0)+1, All_Stats!$P:$P,"<>Email Marketing" ) -> 134 | E12: =SUMIFS(All_Stats!$I:$I, All_Stats!$D:$D,$B12, All_Stats!$B:$B,">="&EOMONTH($A12,-1)+1, All_Stats!$B:$B,"<"&EOMONTH($A12,0)+1, All_Stats!$P:$P,"<>Email Marketing" ) -> 12 | F12: =iferror(E12/D12,"N/A") -> 0.089552239 | G12: =SUMIFS(All_Stats!$H:$H, All_Stats!$D:$D,$B12, All_Stats!$B:$B,">="&EOMONTH($A12,-1)+1, All_Stats!$B:$B,"<"&EOMONTH($A12,0)+1, All_Stats!$P:$P,"<>Email Marketing" ) -> 60 | H12: =SUMIFS(All_Stats!$K:$K, All_Stats!$D:$D,$B12, All_Stats!$B:$B,">="&EOMONTH($A12,-1)+1, All_Stats!$B:$B,"<"&EOMONTH($A12,0)+1, All_Stats!$P:$P,"<>Email Marketing" ) -> 62 | I12: =IFERROR(__xludf.DUMMYFUNCTION("COUNTUNIQUEIFS(All_Stats!A:A, All_Stats!$D:$D,$B12, All_Stats!$B:$B,"">=""&EOMONTH($A12,-1)+1, All_Stats!$B:$B,""<""&EOMONTH($A12,0)+1, All_Stats!$P:$P,""<>Email Marketing"" )"),11.0) -> 11
A13: 45352 | B13: V4 | C13: =if(ifna(VLOOKUP(B13,'Vendor Directory'!A:C,3,0),"NOT FOUND")="","NOT FOUND",VLOOKUP(B13,'Vendor Directory'!A:C,3,0)) -> Vendor 2 Name | D13: =SUMIFS(All_Stats!$G:$G, All_Stats!$D:$D,$B13, All_Stats!$B:$B,">="&EOMONTH($A13,-1)+1, All_Stats!$B:$B,"<"&EOMONTH($A13,0)+1, All_Stats!$P:$P,"<>Email Marketing" ) -> 0 | E13: =SUMIFS(All_Stats!$I:$I, All_Stats!$D:$D,$B13, All_Stats!$B:$B,">="&EOMONTH($A13,-1)+1, All_Stats!$B:$B,"<"&EOMONTH($A13,0)+1, All_Stats!$P:$P,"<>Email Marketing" ) -> 0 | F13: =iferror(E13/D13,"N/A") -> N/A | G13: =SUMIFS(All_Stats!$H:$H, All_Stats!$D:$D,$B13, All_Stats!$B:$B,">="&EOMONTH($A13,-1)+1, All_Stats!$B:$B,"<"&EOMONTH($A13,0)+1, All_Stats!$P:$P,"<>Email Marketing" ) -> 0 | H13: =SUMIFS(All_Stats!$K:$K, All_Stats!$D:$D,$B13, All_Stats!$B:$B,">="&EOMONTH($A13,-1)+1, All_Stats!$B:$B,"<"&EOMONTH($A13,0)+1, All_Stats!$P:$P,"<>Email Marketing" ) -> 0 | I13: =IFERROR(__xludf.DUMMYFUNCTION("COUNTUNIQUEIFS(All_Stats!A:A, All_Stats!$D:$D,$B13, All_Stats!$B:$B,"">=""&EOMONTH($A13,-1)+1, All_Stats!$B:$B,""<""&EOMONTH($A13,0)+1, All_Stats!$P:$P,""<>Email Marketing"" )"),4.0) -> 4
A14: 45352 | B14: V39 | C14: Data Science IRC | D14: =SUMIFS(All_Stats!$G:$G, All_Stats!$D:$D,$B14, All_Stats!$B:$B,">="&EOMONTH($A14,-1)+1, All_Stats!$B:$B,"<"&EOMONTH($A14,0)+1, All_Stats!$P:$P,"<>Email Marketing" ) -> 6 | E14: =SUMIFS(All_Stats!$I:$I, All_Stats!$D:$D,$B14, All_Stats!$B:$B,">="&EOMONTH($A14,-1)+1, All_Stats!$B:$B,"<"&EOMONTH($A14,0)+1, All_Stats!$P:$P,"<>Email Marketing" ) -> 0 | F14: =iferror(E14/D14,"N/A") -> 0 | G14: =SUMIFS(All_Stats!$H:$H, All_Stats!$D:$D,$B14, All_Stats!$B:$B,">="&EOMONTH($A14,-1)+1, All_Stats!$B:$B,"<"&EOMONTH($A14,0)+1, All_Stats!$P:$P,"<>Email Marketing" ) -> 0 | H14: =SUMIFS(All_Stats!$K:$K, All_Stats!$D:$D,$B14, All_Stats!$B:$B,">="&EOMONTH($A14,-1)+1, All_Stats!$B:$B,"<"&EOMONTH($A14,0)+1, All_Stats!$P:$P,"<>Email Marketing" ) -> 6 | I14: =IFERROR(__xludf.DUMMYFUNCTION("COUNTUNIQUEIFS(All_Stats!A:A, All_Stats!$D:$D,$B14, All_Stats!$B:$B,"">=""&EOMONTH($A14,-1)+1, All_Stats!$B:$B,""<""&EOMONTH($A14,0)+1, All_Stats!$P:$P,""<>Email Marketing"" )"),8.0) -> 8
A15: 45352 | B15: T2 | C15: Phillipines Team | D15: =SUMIFS(All_Stats!$G:$G, All_Stats!$D:$D,$B15, All_Stats!$B:$B,">="&EOMONTH($A15,-1)+1, All_Stats!$B:$B,"<"&EOMONTH($A15,0)+1, All_Stats!$P:$P,"<>Email Marketing" ) -> 2 | E15: =SUMIFS(All_Stats!$I:$I, All_Stats!$D:$D,$B15, All_Stats!$B:$B,">="&EOMONTH($A15,-1)+1, All_Stats!$B:$B,"<"&EOMONTH($A15,0)+1, All_Stats!$P:$P,"<>Email Marketing" ) -> 0 | F15: =iferror(E15/D15,"N/A") -> 0 | G15: =SUMIFS(All_Stats!$H:$H, All_Stats!$D:$D,$B15, All_Stats!$B:$B,">="&EOMONTH($A15,-1)+1, All_Stats!$B:$B,"<"&EOMONTH($A15,0)+1, All_Stats!$P:$P,"<>Email Marketing" ) -> 0 | H15: =SUMIFS(All_Stats!$K:$K, All_Stats!$D:$D,$B15, All_Stats!$B:$B,">="&EOMONTH($A15,-1)+1, All_Stats!$B:$B,"<"&EOMONTH($A15,0)+1, All_Stats!$P:$P,"<>Email Marketing" ) -> 2 | I15: =IFERROR(__xludf.DUMMYFUNCTION("COUNTUNIQUEIFS(All_Stats!A:A, All_Stats!$D:$D,$B15, All_Stats!$B:$B,"">=""&EOMONTH($A15,-1)+1, All_Stats!$B:$B,""<""&EOMONTH($A15,0)+1, All_Stats!$P:$P,""<>Email Marketing"" )"),1.0) -> 1
A16: 45352 | B16: V38 | C16: EvolveBPM | D16: =SUMIFS(All_Stats!$G:$G, All_Stats!$D:$D,$B16, All_Stats!$B:$B,">="&EOMONTH($A16,-1)+1, All_Stats!$B:$B,"<"&EOMONTH($A16,0)+1, All_Stats!$P:$P,"<>Email Marketing" ) -> 0 | E16: =SUMIFS(All_Stats!$I:$I, All_Stats!$D:$D,$B16, All_Stats!$B:$B,">="&EOMONTH($A16,-1)+1, All_Stats!$B:$B,"<"&EOMONTH($A16,0)+1, All_Stats!$P:$P,"<>Email Marketing" ) -> 0 | F16: =iferror(E16/D16,"N/A") -> N/A | G16: =SUMIFS(All_Stats!$H:$H, All_Stats!$D:$D,$B16, All_Stats!$B:$B,">="&EOMONTH($A16,-1)+1, All_Stats!$B:$B,"<"&EOMONTH($A16,0)+1, All_Stats!$P:$P,"<>Email Marketing" ) -> 0 | H16: =SUMIFS(All_Stats!$K:$K, All_Stats!$D:$D,$B16, All_Stats!$B:$B,">="&EOMONTH($A16,-1)+1, All_Stats!$B:$B,"<"&EOMONTH($A16,0)+1, All_Stats!$P:$P,"<>Email Marketing" ) -> 0 | I16: =IFERROR(__xludf.DUMMYFUNCTION("COUNTUNIQUEIFS(All_Stats!A:A, All_Stats!$D:$D,$B16, All_Stats!$B:$B,"">=""&EOMONTH($A16,-1)+1, All_Stats!$B:$B,""<""&EOMONTH($A16,0)+1, All_Stats!$P:$P,""<>Email Marketing"" )"),2.0) -> 2
A17: 45352 | B17: V36 | C17: Coleda | D17: =SUMIFS(All_Stats!$G:$G, All_Stats!$D:$D,$B17, All_Stats!$B:$B,">="&EOMONTH($A17,-1)+1, All_Stats!$B:$B,"<"&EOMONTH($A17,0)+1, All_Stats!$P:$P,"<>Email Marketing" ) -> 0 | E17: =SUMIFS(All_Stats!$I:$I, All_Stats!$D:$D,$B17, All_Stats!$B:$B,">="&EOMONTH($A17,-1)+1, All_Stats!$B:$B,"<"&EOMONTH($A17,0)+1, All_Stats!$P:$P,"<>Email Marketing" ) -> 0 | F17: =iferror(E17/D17,"N/A") -> N/A | G17: =SUMIFS(All_Stats!$H:$H, All_Stats!$D:$D,$B17, All_Stats!$B:$B,">="&EOMONTH($A17,-1)+1, All_Stats!$B:$B,"<"&EOMONTH($A17,0)+1, All_Stats!$P:$P,"<>Email Marketing" ) -> 0 | H17: =SUMIFS(All_Stats!$K:$K, All_Stats!$D:$D,$B17, All_Stats!$B:$B,">="&EOMONTH($A17,-1)+1, All_Stats!$B:$B,"<"&EOMONTH($A17,0)+1, All_Stats!$P:$P,"<>Email Marketing" ) -> 0 | I17: =IFERROR(__xludf.DUMMYFUNCTION("COUNTUNIQUEIFS(All_Stats!A:A, All_Stats!$D:$D,$B17, All_Stats!$B:$B,"">=""&EOMONTH($A17,-1)+1, All_Stats!$B:$B,""<""&EOMONTH($A17,0)+1, All_Stats!$P:$P,""<>Email Marketing"" )"),1.0) -> 1
C18: Total | D18: =SUM(D9:D16) -> 358 | E18: =SUM(E9:E16) -> 61 | F18: =iferror(E18/D18,"N/A") -> 0.17039106 | G18: =SUM(G9:G16) -> 131 | H18: =SUM(H9:H16) -> 166
D20: =D6+D18 -> 2169 | E20: =E6+E18 -> 329 | G20: =G6+G18 -> 358 | H20: =H6+H18 -> 1482

Sheet Copy of Montly Stats
A1: 2021
A2: Month | B2: Vendor ID | C2: Vendor Name | D2: Delivered | E2: Rejected | F2: Rejection Rate | G2: Accepted | H2: Pending | I2: N Unique CIDS | K2: Total N Unique Cids
A3: 44287 | B3: V1 | C3: =if(ifna(VLOOKUP(B3,'Vendor Directory'!A:C,3,0),"NOT FOUND")="","NOT FOUND",VLOOKUP(B3,'Vendor Directory'!A:C,3,0)) -> #N/A | D3: =SUMIFS(All_Stats!$G:$G, All_Stats!$D:$D,$B3, All_Stats!$B:$B,">="&EOMONTH($A3,-1)+1, All_Stats!$B:$B,"<"&EOMONTH($A3,0)+1 ) -> 0 | E3: =SUMIFS(All_Stats!$I:$I, All_Stats!$D:$D,$B3, All_Stats!$B:$B,">="&EOMONTH($A3,-1)+1, All_Stats!$B:$B,"<"&EOMONTH($A3,0)+1 ) -> 0 | F3: =iferror(E3/D3,"N/A") -> N/A | G3: =SUMIFS(All_Stats!$H:$H, All_Stats!$D:$D,$B3, All_Stats!$B:$B,">="&EOMONTH($A3,-1)+1, All_Stats!$B:$B,"<"&EOMONTH($A3,0)+1 ) -> 0 | H3: =SUMIFS(All_Stats!$K:$K, All_Stats!$D:$D,$B3, All_Stats!$B:$B,">="&EOMONTH($A3,-1)+1, All_Stats!$B:$B,"<"&EOMONTH($A3,0)+1 ) -> 0 | I3: =IFERROR(__xludf.DUMMYFUNCTION("COUNTUNIQUEIFS(All_Stats!A:A, All_Stats!$D:$D,$B3, All_Stats!$B:$B,"">=""&EOMONTH($A3,-1)+1, All_Stats!$B:$B,""<""&EOMONTH($A3,0)+1)"),0.0) -> 0 | K3: =IFERROR(__xludf.DUMMYFUNCTION("COUNTUNIQUEIFS(All_Stats!A:A, All_Stats!$B:$B,"">=""&EOMONTH($A3,-1)+1, All_Stats!$B:$B,""<""&EOMONTH($A3,0)+1)"),0.0) -> 0
A4: 44287 | B4: V2 | C4: =if(ifna(VLOOKUP(B4,'Vendor Directory'!A:C,3,0),"NOT FOUND")="","NOT FOUND",VLOOKUP(B4,'Vendor Directory'!A:C,3,0)) -> #N/A | D4: =SUMIFS(All_Stats!$G:$G, All_Stats!$D:$D,$B4, All_Stats!$B:$B,">="&EOMONTH($A4,-1)+1, All_Stats!$B:$B,"<"&EOMONTH($A4,0)+1 ) -> 0 | E4: =SUMIFS(All_Stats!$I:$I, All_Stats!$D:$D,$B4, All_Stats!$B:$B,">="&EOMONTH($A4,-1)+1, All_Stats!$B:$B,"<"&EOMONTH($A4,0)+1 ) -> 0 | F4: =iferror(E4/D4,"N/A") -> N/A | G4: =SUMIFS(All_Stats!$H:$H, All_Stats!$D:$D,$B4, All_Stats!$B:$B,">="&EOMONTH($A4,-1)+1, All_Stats!$B:$B,"<"&EOMONTH($A4,0)+1 ) -> 0 | H4: =SUMIFS(All_Stats!$K:$K, All_Stats!$D:$D,$B4, All_Stats!$B:$B,">="&EOMONTH($A4,-1)+1, All_Stats!$B:$B,"<"&EOMONTH($A4,0)+1 ) -> 0 | I4: =IFERROR(__xludf.DUMMYFUNCTION("COUNTUNIQUEIFS(All_Stats!A:A, All_Stats!$D:$D,$B4, All_Stats!$B:$B,"">=""&EOMONTH($A4,-1)+1, All_Stats!$B:$B,""<""&EOMONTH($A4,0)+1)"),0.0) -> 0
A5: 44287 | B5: V3 | C5: =if(ifna(VLOOKUP(B5,'Vendor Directory'!A:C,3,0),"NOT FOUND")="","NOT FOUND",VLOOKUP(B5,'Vendor Directory'!A:C,3,0)) -> #N/A | D5: =SUMIFS(All_Stats!$G:$G, All_Stats!$D:$D,$B5, All_Stats!$B:$B,">="&EOMONTH($A5,-1)+1, All_Stats!$B:$B,"<"&EOMONTH($A5,0)+1 ) -> 0 | E5: =SUMIFS(All_Stats!$I:$I, All_Stats!$D:$D,$B5, All_Stats!$B:$B,">="&EOMONTH($A5,-1)+1, All_Stats!$B:$B,"<"&EOMONTH($A5,0)+1 ) -> 0 | F5: =iferror(E5/D5,"N/A") -> N/A | G5: =SUMIFS(All_Stats!$H:$H, All_Stats!$D:$D,$B5, All_Stats!$B:$B,">="&EOMONTH($A5,-1)+1, All_Stats!$B:$B,"<"&EOMONTH($A5,0)+1 ) -> 0 | H5: =SUMIFS(All_Stats!$K:$K, All_Stats!$D:$D,$B5, All_Stats!$B:$B,">="&EOMONTH($A5,-1)+1, All_Stats!$B:$B,"<"&EOMONTH($A5,0)+1 ) -> 0 | I5: =IFERROR(__xludf.DUMMYFUNCTION("COUNTUNIQUEIFS(All_Stats!A:A, All_Stats!$D:$D,$B5, All_Stats!$B:$B,"">=""&EOMONTH($A5,-1)+1, All_Stats!$B:$B,""<""&EOMONTH($A5,0)+1)"),0.0) -> 0
A6: 44287 | B6: V4 | C6: =if(ifna(VLOOKUP(B6,'Vendor Directory'!A:C,3,0),"NOT FOUND")="","NOT FOUND",VLOOKUP(B6,'Vendor Directory'!A:C,3,0)) -> Vendor 2 Name | D6: =SUMIFS(All_Stats!$G:$G, All_Stats!$D:$D,$B6, All_Stats!$B:$B,">="&EOMONTH($A6,-1)+1, All_Stats!$B:$B,"<"&EOMONTH($A6,0)+1 ) -> 0 | E6: =SUMIFS(All_Stats!$I:$I, All_Stats!$D:$D,$B6, All_Stats!$B:$B,">="&EOMONTH($A6,-1)+1, All_Stats!$B:$B,"<"&EOMONTH($A6,0)+1 ) -> 0 | F6: =iferror(E6/D6,"N/A") -> N/A | G6: =SUMIFS(All_Stats!$H:$H, All_Stats!$D:$D,$B6, All_Stats!$B:$B,">="&EOMONTH($A6,-1)+1, All_Stats!$B:$B,"<"&EOMONTH($A6,0)+1 ) -> 0 | H6: =SUMIFS(All_Stats!$K:$K, All_Stats!$D:$D,$B6, All_Stats!$B:$B,">="&EOMONTH($A6,-1)+1, All_Stats!$B:$B,"<"&EOMONTH($A6,0)+1 ) -> 0 | I6: =IFERROR(__xludf.DUMMYFUNCTION("COUNTUNIQUEIFS(All_Stats!A:A, All_Stats!$D:$D,$B6, All_Stats!$B:$B,"">=""&EOMONTH($A6,-1)+1, All_Stats!$B:$B,""<""&EOMONTH($A6,0)+1)"),0.0) -> 0
A7: 44287 | B7: V5 | C7: =if(ifna(VLOOKUP(B7,'Vendor Directory'!A:C,3,0),"NOT FOUND")="","NOT FOUND",VLOOKUP(B7,'Vendor Directory'!A:C,3,0)) -> #N/A | D7: =SUMIFS(All_Stats!$G:$G, All_Stats!$D:$D,$B7, All_Stats!$B:$B,">="&EOMONTH($A7,-1)+1, All_Stats!$B:$B,"<"&EOMONTH($A7,0)+1 ) -> 0 | E7: =SUMIFS(All_Stats!$I:$I, All_Stats!$D:$D,$B7, All_Stats!$B:$B,">="&EOMONTH($A7,-1)+1, All_Stats!$B:$B,"<"&EOMONTH($A7,0)+1 ) -> 0 | F7: =iferror(E7/D7,"N/A") -> N/A | G7: =SUMIFS(All_Stats!$H:$H, All_Stats!$D:$D,$B7, All_Stats!$B:$B,">="&EOMONTH($A7,-1)+1, All_Stats!$B:$B,"<"&EOMONTH($A7,0)+1 ) -> 0 | H7: =SUMIFS(All_Stats!$K:$K, All_Stats!$D:$D,$B7, All_Stats!$B:$B,">="&EOMONTH($A7,-1)+1, All_Stats!$B:$B,"<"&EOMONTH($A7,0)+1 ) -> 0 | I7: =IFERROR(__xludf.DUMMYFUNCTION("COUNTUNIQUEIFS(All_Stats!A:A, All_Stats!$D:$D,$B7, All_Stats!$B:$B,"">=""&EOMONTH($A7,-1)+1, All_Stats!$B:$B,""<""&EOMONTH($A7,0)+1)"),0.0) -> 0
A8: 44287 | B8: V6 | C8: =if(ifna(VLOOKUP(B8,'Vendor Directory'!A:C,3,0),"NOT FOUND")="","NOT FOUND",VLOOKUP(B8,'Vendor Directory'!A:C,3,0)) -> #N/A | D8: =SUMIFS(All_Stats!$G:$G, All_Stats!$D:$D,$B8, All_Stats!$B:$B,">="&EOMONTH($A8,-1)+1, All_Stats!$B:$B,"<"&EOMONTH($A8,0)+1 ) -> 0 | E8: =SUMIFS(All_Stats!$I:$I, All_Stats!$D:$D,$B8, All_Stats!$B:$B,">="&EOMONTH($A8,-1)+1, All_Stats!$B:$B,"<"&EOMONTH($A8,0)+1 ) -> 0 | F8: =iferror(E8/D8,"N/A") -> N/A | G8: =SUMIFS(All_Stats!$H:$H, All_Stats!$D:$D,$B8, All_Stats!$B:$B,">="&EOMONTH($A8,-1)+1, All_Stats!$B:$B,"<"&EOMONTH($A8,0)+1 ) -> 0 | H8: =SUMIFS(All_Stats!$K:$K, All_Stats!$D:$D,$B8, All_Stats!$B:$B,">="&EOMONTH($A8,-1)+1, All_Stats!$B:$B,"<"&EOMONTH($A8,0)+1 ) -> 0 | I8: =IFERROR(__xludf.DUMMYFUNCTION("COUNTUNIQUEIFS(All_Stats!A:A, All_Stats!$D:$D,$B8, All_Stats!$B:$B,"">=""&EOMONTH($A8,-1)+1, All_Stats!$B:$B,""<""&EOMONTH($A8,0)+1)"),0.0) -> 0
A9: 44287 | B9: V9 | C9: =if(ifna(VLOOKUP(B9,'Vendor Directory'!A:C,3,0),"NOT FOUND")="","NOT FOUND",VLOOKUP(B9,'Vendor Directory'!A:C,3,0)) -> Vendor 3 Name | D9: =SUMIFS(All_Stats!$G:$G, All_Stats!$D:$D,$B9, All_Stats!$B:$B,">="&EOMONTH($A9,-1)+1, All_Stats!$B:$B,"<"&EOMONTH($A9,0)+1 ) -> 0 | E9: =SUMIFS(All_Stats!$I:$I, All_Stats!$D:$D,$B9, All_Stats!$B:$B,">="&EOMONTH($A9,-1)+1, All_Stats!$B:$B,"<"&EOMONTH($A9,0)+1 ) -> 0 | F9: =iferror(E9/D9,"N/A") -> N/A | G9: =SUMIFS(All_Stats!$H:$H, All_Stats!$D:$D,$B9, All_Stats!$B:$B,">="&EOMONTH($A9,-1)+1, All_Stats!$B:$B,"<"&EOMONTH($A9,0)+1 ) -> 0 | H9: =SUMIFS(All_Stats!$K:$K, All_Stats!$D:$D,$B9, All_Stats!$B:$B,">="&EOMONTH($A9,-1)+1, All_Stats!$B:$B,"<"&EOMONTH($A9,0)+1 ) -> 0 | I9: =IFERROR(__xludf.DUMMYFUNCTION("COUNTUNIQUEIFS(All_Stats!A:A, All_Stats!$D:$D,$B9, All_Stats!$B:$B,"">=""&EOMONTH($A9,-1)+1, All_Stats!$B:$B,""<""&EOMONTH($A9,0)+1)"),0.0) -> 0
A10: 44287 | B10: V10 | C10: =if(ifna(VLOOKUP(B10,'Vendor Directory'!A:C,3,0),"NOT FOUND")="","NOT FOUND",VLOOKUP(B10,'Vendor Directory'!A:C,3,0)) -> Vendor 4 Name | D10: =SUMIFS(All_Stats!$G:$G, All_Stats!$D:$D,$B10, All_Stats!$B:$B,">="&EOMONTH($A10,-1)+1, All_Stats!$B:$B,"<"&EOMONTH($A10,0)+1 ) -> 0 | E10: =SUMIFS(All_Stats!$I:$I, All_Stats!$D:$D,$B10, All_Stats!$B:$B,">="&EOMONTH($A10,-1)+1, All_Stats!$B:$B,"<"&EOMONTH($A10,0)+1 ) -> 0 | F10: =iferror(E10/D10,"N/A") -> N/A | G10: =SUMIFS(All_Stats!$H:$H, All_Stats!$D:$D,$B10, All_Stats!$B:$B,">="&EOMONTH($A10,-1)+1, All_Stats!$B:$B,"<"&EOMONTH($A10,0)+1 ) -> 0 | H10: =SUMIFS(All_Stats!$K:$K, All_Stats!$D:$D,$B10, All_Stats!$B:$B,">="&EOMONTH($A10,-1)+1, All_Stats!$B:$B,"<"&EOMONTH($A10,0)+1 ) -> 0 | I10: =IFERROR(__xludf.DUMMYFUNCTION("COUNTUNIQUEIFS(All_Stats!A:A, All_Stats!$D:$D,$B10, All_Stats!$B:$B,"">=""&EOMONTH($A10,-1)+1, All_Stats!$B:$B,""<""&EOMONTH($A10,0)+1)"),0.0) -> 0
A11: 44287 | B11: V11 | C11: =if(ifna(VLOOKUP(B11,'Vendor Directory'!A:C,3,0),"NOT FOUND")="","NOT FOUND",VLOOKUP(B11,'Vendor Directory'!A:C,3,0)) -> #N/A | D11: =SUMIFS(All_Stats!$G:$G, All_Stats!$D:$D,$B11, All_Stats!$B:$B,">="&EOMONTH($A11,-1)+1, All_Stats!$B:$B,"<"&EOMONTH($A11,0)+1 ) -> 0 | E11: =SUMIFS(All_Stats!$I:$I, All_Stats!$D:$D,$B11, All_Stats!$B:$B,">="&EOMONTH($A11,-1)+1, All_Stats!$B:$B,"<"&EOMONTH($A11,0)+1 ) -> 0 | F11: =iferror(E11/D11,"N/A") -> N/A | G11: =SUMIFS(All_Stats!$H:$H, All_Stats!$D:$D,$B11, All_Stats!$B:$B,">="&EOMONTH($A11,-1)+1, All_Stats!$B:$B,"<"&EOMONTH($A11,0)+1 ) -> 0 | H11: =SUMIFS(All_Stats!$K:$K, All_Stats!$D:$D,$B11, All_Stats!$B:$B,">="&EOMONTH($A11,-1)+1, All_Stats!$B:$B,"<"&EOMONTH($A11,0)+1 ) -> 0 | I11: =IFERROR(__xludf.DUMMYFUNCTION("COUNTUNIQUEIFS(All_Stats!A:A, All_Stats!$D:$D,$B11, All_Stats!$B:$B,"">=""&EOMONTH($A11,-1)+1, All_Stats!$B:$B,""<""&EOMONTH($A11,0)+1)"),0.0) -> 0
A12: 44287 | B12: V13 | C12: =if(ifna(VLOOKUP(B12,'Vendor Directory'!A:C,3,0),"NOT FOUND")="","NOT FOUND",VLOOKUP(B12,'Vendor Directory'!A:C,3,0)) -> #N/A | D12: =SUMIFS(All_Stats!$G:$G, All_Stats!$D:$D,$B12, All_Stats!$B:$B,">="&EOMONTH($A12,-1)+1, All_Stats!$B:$B,"<"&EOMONTH($A12,0)+1 ) -> 0 | E12: =SUMIFS(All_Stats!$I:$I, All_Stats!$D:$D,$B12, All_Stats!$B:$B,">="&EOMONTH($A12,-1)+1, All_Stats!$B:$B,"<"&EOMONTH($A12,0)+1 ) -> 0 | F12: =iferror(E12/D12,"N/A") -> N/A | G12: =SUMIFS(All_Stats!$H:$H, All_Stats!$D:$D,$B12, All_Stats!$B:$B,">="&EOMONTH($A12,-1)+1, All_Stats!$B:$B,"<"&EOMONTH($A12,0)+1 ) -> 0 | H12: =SUMIFS(All_Stats!$K:$K, All_Stats!$D:$D,$B12, All_Stats!$B:$B,">="&EOMONTH($A12,-1)+1, All_Stats!$B:$B,"<"&EOMONTH($A12,0)+1 ) -> 0 | I12: =IFERROR(__xludf.DUMMYFUNCTION("COUNTUNIQUEIFS(All_Stats!A:A, All_Stats!$D:$D,$B12, All_Stats!$B:$B,"">=""&EOMONTH($A12,-1)+1, All_Stats!$B:$B,""<""&EOMONTH($A12,0)+1)"),0.0) -> 0
A13: 44287 | B13: V15 | C13: =if(ifna(VLOOKUP(B13,'Vendor Directory'!A:C,3,0),"NOT FOUND")="","NOT FOUND",VLOOKUP(B13,'Vendor Directory'!A:C,3,0)) -> #N/A | D13: =SUMIFS(All_Stats!$G:$G, All_Stats!$D:$D,$B13, All_Stats!$B:$B,">="&EOMONTH($A13,-1)+1, All_Stats!$B:$B,"<"&EOMONTH($A13,0)+1 ) -> 0 | E13: =SUMIFS(All_Stats!$I:$I, All_Stats!$D:$D,$B13, All_Stats!$B:$B,">="&EOMONTH($A13,-1)+1, All_Stats!$B:$B,"<"&EOMONTH($A13,0)+1 ) -> 0 | F13: =iferror(E13/D13,"N/A") -> N/A | G13: =SUMIFS(All_Stats!$H:$H, All_Stats!$D:$D,$B13, All_Stats!$B:$B,">="&EOMONTH($A13,-1)+1, All_Stats!$B:$B,"<"&EOMONTH($A13,0)+1 ) -> 0 | H13: =SUMIFS(All_Stats!$K:$K, All_Stats!$D:$D,$B13, All_Stats!$B:$B,">="&EOMONTH($A13,-1)+1, All_Stats!$B:$B,"<"&EOMONTH($A13,0)+1 ) -> 0 | I13: =IFERROR(__xludf.DUMMYFUNCTION("COUNTUNIQUEIFS(All_Stats!A:A, All_Stats!$D:$D,$B13, All_Stats!$B:$B,"">=""&EOMONTH($A13,-1)+1, All_Stats!$B:$B,""<""&EOMONTH($A13,0)+1)"),0.0) -> 0
A14: 44287 | B14: V17 | C14: =if(ifna(VLOOKUP(B14,'Vendor Directory'!A:C,3,0),"NOT FOUND")="","NOT FOUND",VLOOKUP(B14,'Vendor Directory'!A:C,3,0)) -> #N/A | D14: =SUMIFS(All_Stats!$G:$G, All_Stats!$D:$D,$B14, All_Stats!$B:$B,">="&EOMONTH($A14,-1)+1, All_Stats!$B:$B,"<"&EOMONTH($A14,0)+1 ) -> 0 | E14: =SUMIFS(All_Stats!$I:$I, All_Stats!$D:$D,$B14, All_Stats!$B:$B,">="&EOMONTH($A14,-1)+1, All_Stats!$B:$B,"<"&EOMONTH($A14,0)+1 ) -> 0 | F14: =iferror(E14/D14,"N/A") -> N/A | G14: =SUMIFS(All_Stats!$H:$H, All_Stats!$D:$D,$B14, All_Stats!$B:$B,">="&EOMONTH($A14,-1)+1, All_Stats!$B:$B,"<"&EOMONTH($A14,0)+1 ) -> 0 | H14: =SUMIFS(All_Stats!$K:$K, All_Stats!$D:$D,$B14, All_Stats!$B:$B,">="&EOMONTH($A14,-1)+1, All_Stats!$B:$B,"<"&EOMONTH($A14,0)+1 ) -> 0 | I14: =IFERROR(__xludf.DUMMYFUNCTION("COUNTUNIQUEIFS(All_Stats!A:A, All_Stats!$D:$D,$B14, All_Stats!$B:$B,"">=""&EOMONTH($A14,-1)+1, All_Stats!$B:$B,""<""&EOMONTH($A14,0)+1)"),0.0) -> 0
A15: 44287 | B15: V19 | C15: =if(ifna(VLOOKUP(B15,'Vendor Directory'!A:C,3,0),"NOT FOUND")="","NOT FOUND",VLOOKUP(B15,'Vendor Directory'!A:C,3,0)) -> #N/A | D15: =SUMIFS(All_Stats!$G:$G, All_Stats!$D:$D,$B15, All_Stats!$B:$B,">="&EOMONTH($A15,-1)+1, All_Stats!$B:$B,"<"&EOMONTH($A15,0)+1 ) -> 0 | E15: =SUMIFS(All_Stats!$I:$I, All_Stats!$D:$D,$B15, All_Stats!$B:$B,">="&EOMONTH($A15,-1)+1, All_Stats!$B:$B,"<"&EOMONTH($A15,0)+1 ) -> 0 | F15: =iferror(E15/D15,"N/A") -> N/A | G15: =SUMIFS(All_Stats!$H:$H, All_Stats!$D:$D,$B15, All_Stats!$B:$B,">="&EOMONTH($A15,-1)+1, All_Stats!$B:$B,"<"&EOMONTH($A15,0)+1 ) -> 0 | H15: =SUMIFS(All_Stats!$K:$K, All_Stats!$D:$D,$B15, All_Stats!$B:$B,">="&EOMONTH($A15,-1)+1, All_Stats!$B:$B,"<"&EOMONTH($A15,0)+1 ) -> 0 | I15: =IFERROR(__xludf.DUMMYFUNCTION("COUNTUNIQUEIFS(All_Stats!A:A, All_Stats!$D:$D,$B15, All_Stats!$B:$B,"">=""&EOMONTH($A15,-1)+1, All_Stats!$B:$B,""<""&EOMONTH($A15,0)+1)"),0.0) -> 0
A16: 44287 | B16: V20 | C16: =if(ifna(VLOOKUP(B16,'Vendor Directory'!A:C,3,0),"NOT FOUND")="","NOT FOUND",VLOOKUP(B16,'Vendor Directory'!A:C,3,0)) -> #N/A | D16: =SUMIFS(All_Stats!$G:$G, All_Stats!$D:$D,$B16, All_Stats!$B:$B,">="&EOMONTH($A16,-1)+1, All_Stats!$B:$B,"<"&EOMONTH($A16,0)+1 ) -> 0 | E16: =SUMIFS(All_Stats!$I:$I, All_Stats!$D:$D,$B16, All_Stats!$B:$B,">="&EOMONTH($A16,-1)+1, All_Stats!$B:$B,"<"&EOMONTH($A16,0)+1 ) -> 0 | F16: =iferror(E16/D16,"N/A") -> N/A | G16: =SUMIFS(All_Stats!$H:$H, All_Stats!$D:$D,$B16, All_Stats!$B:$B,">="&EOMONTH($A16,-1)+1, All_Stats!$B:$B,"<"&EOMONTH($A16,0)+1 ) -> 0 | H16: =SUMIFS(All_Stats!$K:$K, All_Stats!$D:$D,$B16, All_Stats!$B:$B,">="&EOMONTH($A16,-1)+1, All_Stats!$B:$B,"<"&EOMONTH($A16,0)+1 ) -> 0 | I16: =IFERROR(__xludf.DUMMYFUNCTION("COUNTUNIQUEIFS(All_Stats!A:A, All_Stats!$D:$D,$B16, All_Stats!$B:$B,"">=""&EOMONTH($A16,-1)+1, All_Stats!$B:$B,""<""&EOMONTH($A16,0)+1)"),0.0) -> 0
A17: 44287 | B17: V22 | C17: =if(ifna(VLOOKUP(B17,'Vendor Directory'!A:C,3,0),"NOT FOUND")="","NOT FOUND",VLOOKUP(B17,'Vendor Directory'!A:C,3,0)) -> #N/A | D17: =SUMIFS(All_Stats!$G:$G, All_Stats!$D:$D,$B17, All_Stats!$B:$B,">="&EOMONTH($A17,-1)+1, All_Stats!$B:$B,"<"&EOMONTH($A17,0)+1 ) -> 0 | E17: =SUMIFS(All_Stats!$I:$I, All_Stats!$D:$D,$B17, All_Stats!$B:$B,">="&EOMONTH($A17,-1)+1, All_Stats!$B:$B,"<"&EOMONTH($A17,0)+1 ) -> 0 | F17: =iferror(E17/D17,"N/A") -> N/A | G17: =SUMIFS(All_Stats!$H:$H, All_Stats!$D:$D,$B17, All_Stats!$B:$B,">="&EOMONTH($A17,-1)+1, All_Stats!$B:$B,"<"&EOMONTH($A17,0)+1 ) -> 0 | H17: =SUMIFS(All_Stats!$K:$K, All_Stats!$D:$D,$B17, All_Stats!$B:$B,">="&EOMONTH($A17,-1)+1, All_Stats!$B:$B,"<"&EOMONTH($A17,0)+1 ) -> 0 | I17: =IFERROR(__xludf.DUMMYFUNCTION("COUNTUNIQUEIFS(All_Stats!A:A, All_Stats!$D:$D,$B17, All_Stats!$B:$B,"">=""&EOMONTH($A17,-1)+1, All_Stats!$B:$B,""<""&EOMONTH($A17,0)+1)"),0.0) -> 0
A18: 44287 | B18: V23 | C18: =if(ifna(VLOOKUP(B18,'Vendor Directory'!A:C,3,0),"NOT FOUND")="","NOT FOUND",VLOOKUP(B18,'Vendor Directory'!A:C,3,0)) -> #N/A | D18: =SUMIFS(All_Stats!$G:$G, All_Stats!$D:$D,$B18, All_Stats!$B:$B,">="&EOMONTH($A18,-1)+1, All_Stats!$B:$B,"<"&EOMONTH($A18,0)+1 ) -> 0 | E18: =SUMIFS(All_Stats!$I:$I, All_Stats!$D:$D,$B18, All_Stats!$B:$B,">="&EOMONTH($A18,-1)+1, All_Stats!$B:$B,"<"&EOMONTH($A18,0)+1 ) -> 0 | F18: =iferror(E18/D18,"N/A") -> N/A | G18: =SUMIFS(All_Stats!$H:$H, All_Stats!$D:$D,$B18, All_Stats!$B:$B,">="&EOMONTH($A18,-1)+1, All_Stats!$B:$B,"<"&EOMONTH($A18,0)+1 ) -> 0 | H18: =SUMIFS(All_Stats!$K:$K, All_Stats!$D:$D,$B18, All_Stats!$B:$B,">="&EOMONTH($A18,-1)+1, All_Stats!$B:$B,"<"&EOMONTH($A18,0)+1 ) -> 0 | I18: =IFERROR(__xludf.DUMMYFUNCTION("COUNTUNIQUEIFS(All_Stats!A:A, All_Stats!$D:$D,$B18, All_Stats!$B:$B,"">=""&EOMONTH($A18,-1)+1, All_Stats!$B:$B,""<""&EOMONTH($A18,0)+1)"),0.0) -> 0
A19: 44287 | B19: V24 | C19: =if(ifna(VLOOKUP(B19,'Vendor Directory'!A:C,3,0),"NOT FOUND")="","NOT FOUND",VLOOKUP(B19,'Vendor Directory'!A:C,3,0)) -> #N/A | D19: =SUMIFS(All_Stats!$G:$G, All_Stats!$D:$D,$B19, All_Stats!$B:$B,">="&EOMONTH($A19,-1)+1, All_Stats!$B:$B,"<"&EOMONTH($A19,0)+1 ) -> 0 | E19: =SUMIFS(All_Stats!$I:$I, All_Stats!$D:$D,$B19, All_Stats!$B:$B,">="&EOMONTH($A19,-1)+1, All_Stats!$B:$B,"<"&EOMONTH($A19,0)+1 ) -> 0 | F19: =iferror(E19/D19,"N/A") -> N/A | G19: =SUMIFS(All_Stats!$H:$H, All_Stats!$D:$D,$B19, All_Stats!$B:$B,">="&EOMONTH($A19,-1)+1, All_Stats!$B:$B,"<"&EOMONTH($A19,0)+1 ) -> 0 | H19: =SUMIFS(All_Stats!$K:$K, All_Stats!$D:$D,$B19, All_Stats!$B:$B,">="&EOMONTH($A19,-1)+1, All_Stats!$B:$B,"<"&EOMONTH($A19,0)+1 ) -> 0 | I19: =IFERROR(__xludf.DUMMYFUNCTION("COUNTUNIQUEIFS(All_Stats!A:A, All_Stats!$D:$D,$B19, All_Stats!$B:$B,"">=""&EOMONTH($A19,-1)+1, All_Stats!$B:$B,""<""&EOMONTH($A19,0)+1)"),0.0) -> 0
A20: 44287 | B20: V27 | C20: =if(ifna(VLOOKUP(B20,'Vendor Directory'!A:C,3,0),"NOT FOUND")="","NOT FOUND",VLOOKUP(B20,'Vendor Directory'!A:C,3,0)) -> #N/A | D20: =SUMIFS(All_Stats!$G:$G, All_Stats!$D:$D,$B20, All_Stats!$B:$B,">="&EOMONTH($A20,-1)+1, All_Stats!$B:$B,"<"&EOMONTH($A20,0)+1 ) -> 0 | E20: =SUMIFS(All_Stats!$I:$I, All_Stats!$D:$D,$B20, All_Stats!$B:$B,">="&EOMONTH($A20,-1)+1, All_Stats!$B:$B,"<"&EOMONTH($A20,0)+1 ) -> 0 | F20: =iferror(E20/D20,"N/A") -> N/A | G20: =SUMIFS(All_Stats!$H:$H, All_Stats!$D:$D,$B20, All_Stats!$B:$B,">="&EOMONTH($A20,-1)+1, All_Stats!$B:$B,"<"&EOMONTH($A20,0)+1 ) -> 0 | H20: =SUMIFS(All_Stats!$K:$K, All_Stats!$D:$D,$B20, All_Stats!$B:$B,">="&EOMONTH($A20,-1)+1, All_Stats!$B:$B,"<"&EOMONTH($A20,0)+1 ) -> 0 | I20: =IFERROR(__xludf.DUMMYFUNCTION("COUNTUNIQUEIFS(All_Stats!A:A, All_Stats!$D:$D,$B20, All_Stats!$B:$B,"">=""&EOMONTH($A20,-1)+1, All_Stats!$B:$B,""<""&EOMONTH($A20,0)+1)"),0.0) -> 0
C21: Total | D21: =SUM(D3:D20) -> 0 | E21: =SUM(E3:E20) -> 0 | F21: =iferror(E21/D21,"N/A") -> N/A | G21: =SUM(G3:G20) -> 0 | H21: =SUM(H3:H20) -> 0 | I21: =IFERROR(__xludf.DUMMYFUNCTION("COUNTUNIQUEIFS(All_Stats!A:A, All_Stats!$B:$B,"">=""&EOMONTH($A3,-1)+1, All_Stats!$B:$B,""<""&EOMONTH($A3,0)+1)"),0.0) -> 0
C23: Email marketing
A24: Month | B24: Vendor ID | C24: Vendor Name | D24: Delivered | E24: Rejected | F24: Rejection Rate | G24: Accepted | H24: Pending | I24: N Unique CIDS
A25: 44317 | B25: V5 | C25: =if(ifna(VLOOKUP(B25,'Vendor Directory'!A:C,3,0),"NOT FOUND")="","NOT FOUND",VLOOKUP(B25,'Vendor Directory'!A:C,3,0)) -> #N/A | D25: =SUMIFS(All_Stats!$G:$G, All_Stats!$D:$D,$B25, All_Stats!$B:$B,">="&EOMONTH($A25,-1)+1, All_Stats!$B:$B,"<"&EOMONTH($A25,0)+1, All_Stats!$P:$P,"Email Marketing" ) -> 0 | E25: =SUMIFS(All_Stats!$I:$I, All_Stats!$D:$D,$B25, All_Stats!$B:$B,">="&EOMONTH($A25,-1)+1, All_Stats!$B:$B,"<"&EOMONTH($A25,0)+1, All_Stats!$P:$P,"Email Marketing" ) -> 0 | F25: =iferror(E25/D25,"N/A") -> N/A | G25: =SUMIFS(All_Stats!$H:$H, All_Stats!$D:$D,$B25, All_Stats!$B:$B,">="&EOMONTH($A25,-1)+1, All_Stats!$B:$B,"<"&EOMONTH($A25,0)+1, All_Stats!$P:$P,"Email Marketing" ) -> 0 | H25: =SUMIFS(All_Stats!$K:$K, All_Stats!$D:$D,$B25, All_Stats!$B:$B,">="&EOMONTH($A25,-1)+1, All_Stats!$B:$B,"<"&EOMONTH($A25,0)+1, All_Stats!$P:$P,"Email Marketing" ) -> 0 | I25: =IFERROR(__xludf.DUMMYFUNCTION("COUNTUNIQUEIFS(All_Stats!A:A, All_Stats!$D:$D,$B25, All_Stats!$B:$B,"">=""&EOMONTH($A25,-1)+1, All_Stats!$B:$B,""<""&EOMONTH($A25,0)+1, All_Stats!$P:$P,""Email Marketing"" )"),0.0) -> 0
A26: 44317 | B26: V6 | C26: =if(ifna(VLOOKUP(B26,'Vendor Directory'!A:C,3,0),"NOT FOUND")="","NOT FOUND",VLOOKUP(B26,'Vendor Directory'!A:C,3,0)) -> #N/A | D26: =SUMIFS(All_Stats!$G:$G, All_Stats!$D:$D,$B26, All_Stats!$B:$B,">="&EOMONTH($A26,-1)+1, All_Stats!$B:$B,"<"&EOMONTH($A26,0)+1, All_Stats!$P:$P,"Email Marketing" ) -> 0 | E26: =SUMIFS(All_Stats!$I:$I, All_Stats!$D:$D,$B26, All_Stats!$B:$B,">="&EOMONTH($A26,-1)+1, All_Stats!$B:$B,"<"&EOMONTH($A26,0)+1, All_Stats!$P:$P,"Email Marketing" ) -> 0 | F26: =iferror(E26/D26,"N/A") -> N/A | G26: =SUMIFS(All_Stats!$H:$H, All_Stats!$D:$D,$B26, All_Stats!$B:$B,">="&EOMONTH($A26,-1)+1, All_Stats!$B:$B,"<"&EOMONTH($A26,0)+1, All_Stats!$P:$P,"Email Marketing" ) -> 0 | H26: =SUMIFS(All_Stats!$K:$K, All_Stats!$D:$D,$B26, All_Stats!$B:$B,">="&EOMONTH($A26,-1)+1, All_Stats!$B:$B,"<"&EOMONTH($A26,0)+1, All_Stats!$P:$P,"Email Marketing" ) -> 0 | I26: =IFERROR(__xludf.DUMMYFUNCTION("COUNTUNIQUEIFS(All_Stats!A:A, All_Stats!$D:$D,$B26, All_Stats!$B:$B,"">=""&EOMONTH($A26,-1)+1, All_Stats!$B:$B,""<""&EOMONTH($A26,0)+1, All_Stats!$P:$P,""Email Marketing"" )"),0.0) -> 0
A27: 44317 | B27: V15 | C27: =if(ifna(VLOOKUP(B27,'Vendor Directory'!A:C,3,0),"NOT FOUND")="","NOT FOUND",VLOOKUP(B27,'Vendor Directory'!A:C,3,0)) -> #N/A | D27: =SUMIFS(All_Stats!$G:$G, All_Stats!$D:$D,$B27, All_Stats!$B:$B,">="&EOMONTH($A27,-1)+1, All_Stats!$B:$B,"<"&EOMONTH($A27,0)+1, All_Stats!$P:$P,"Email Marketing" ) -> 0 | E27: =SUMIFS(All_Stats!$I:$I, All_Stats!$D:$D,$B27, All_Stats!$B:$B,">="&EOMONTH($A27,-1)+1, All_Stats!$B:$B,"<"&EOMONTH($A27,0)+1, All_Stats!$P:$P,"Email Marketing" ) -> 0 | F27: =iferror(E27/D27,"N/A") -> N/A | G27: =SUMIFS(All_Stats!$H:$H, All_Stats!$D:$D,$B27, All_Stats!$B:$B,">="&EOMONTH($A27,-1)+1, All_Stats!$B:$B,"<"&EOMONTH($A27,0)+1, All_Stats!$P:$P,"Email Marketing" ) -> 0 | H27: =SUMIFS(All_Stats!$K:$K, All_Stats!$D:$D,$B27, All_Stats!$B:$B,">="&EOMONTH($A27,-1)+1, All_Stats!$B:$B,"<"&EOMONTH($A27,0)+1, All_Stats!$P:$P,"Email Marketing" ) -> 0 | I27: =IFERROR(__xludf.DUMMYFUNCTION("COUNTUNIQUEIFS(All_Stats!A:A, All_Stats!$D:$D,$B27, All_Stats!$B:$B,"">=""&EOMONTH($A27,-1)+1, All_Stats!$B:$B,""<""&EOMONTH($A27,0)+1, All_Stats!$P:$P,""Email Marketing"" )"),0.0) -> 0
C28: Total | D28: =SUM(D25:D27) -> 0 | E28: =SUM(E25:E27) -> 0 | F28: =iferror(E28/D28,"N/A") -> N/A | G28: =SUM(G25:G27) -> 0 | H28: =SUM(H25:H27) -> 0 | I28: =IFERROR(__xludf.DUMMYFUNCTION("COUNTUNIQUEIFS(All_Stats!A:A, All_Stats!$B:$B,"">=""&EOMONTH(#REF!,-1)+1, All_Stats!$B:$B,""<""&EOMONTH(#REF!,0)+1, All_Stats!$P:$P,""Email Marketing"" )"),0.0) -> 0
C30: NOT Email marketing
A31: Month | B31: Vendor ID | C31: Vendor Name | D31: Delivered | E31: Rejected | F31: Rejection Rate | G31: Accepted | H31: Pending | I31: N Unique CIDS
A32: 44317 | B32: V1 | C32: =if(ifna(VLOOKUP(B32,'Vendor Directory'!A:C,3,0),"NOT FOUND")="","NOT FOUND",VLOOKUP(B32,'Vendor Directory'!A:C,3,0)) -> #N/A | D32: =SUMIFS(All_Stats!$G:$G, All_Stats!$D:$D,$B32, All_Stats!$B:$B,">="&EOMONTH($A32,-1)+1, All_Stats!$B:$B,"<"&EOMONTH($A32,0)+1, All_Stats!$P:$P,"<>Email Marketing" ) -> 0 | E32: =SUMIFS(All_Stats!$I:$I, All_Stats!$D:$D,$B32, All_Stats!$B:$B,">="&EOMONTH($A32,-1)+1, All_Stats!$B:$B,"<"&EOMONTH($A32,0)+1, All_Stats!$P:$P,"<>Email Marketing" ) -> 0 | F32: =iferror(E32/D32,"N/A") -> N/A | G32: =SUMIFS(All_Stats!$H:$H, All_Stats!$D:$D,$B32, All_Stats!$B:$B,">="&EOMONTH($A32,-1)+1, All_Stats!$B:$B,"<"&EOMONTH($A32,0)+1, All_Stats!$P:$P,"<>Email Marketing" ) -> 0 | H32: =SUMIFS(All_Stats!$K:$K, All_Stats!$D:$D,$B32, All_Stats!$B:$B,">="&EOMONTH($A32,-1)+1, All_Stats!$B:$B,"<"&EOMONTH($A32,0)+1, All_Stats!$P:$P,"<>Email Marketing" ) -> 0 | I32: =IFERROR(__xludf.DUMMYFUNCTION("COUNTUNIQUEIFS(All_Stats!A:A, All_Stats!$D:$D,$B32, All_Stats!$B:$B,"">=""&EOMONTH($A32,-1)+1, All_Stats!$B:$B,""<""&EOMONTH($A32,0)+1, All_Stats!$P:$P,""<>Email Marketing"" )"),0.0) -> 0 | K32: =IFERROR(__xludf.DUMMYFUNCTION("COUNTUNIQUEIFS(All_Stats!A:A, All_Stats!$B:$B,"">=""&EOMONTH($A32,-1)+1, All_Stats!$B:$B,""<""&EOMONTH($A32,0)+1)"),0.0) -> 0
A33: 44317 | B33: V2 | C33: =if(ifna(VLOOKUP(B33,'Vendor Directory'!A:C,3,0),"NOT FOUND")="","NOT FOUND",VLOOKUP(B33,'Vendor Directory'!A:C,3,0)) -> #N/A | D33: =SUMIFS(All_Stats!$G:$G, All_Stats!$D:$D,$B33, All_Stats!$B:$B,">="&EOMONTH($A33,-1)+1, All_Stats!$B:$B,"<"&EOMONTH($A33,0)+1, All_Stats!$P:$P,"<>Email Marketing" ) -> 0 | E33: =SUMIFS(All_Stats!$I:$I, All_Stats!$D:$D,$B33, All_Stats!$B:$B,">="&EOMONTH($A33,-1)+1, All_Stats!$B:$B,"<"&EOMONTH($A33,0)+1, All_Stats!$P:$P,"<>Email Marketing" ) -> 0 | F33: =iferror(E33/D33,"N/A") -> N/A | G33: =SUMIFS(All_Stats!$H:$H, All_Stats!$D:$D,$B33, All_Stats!$B:$B,">="&EOMONTH($A33,-1)+1, All_Stats!$B:$B,"<"&EOMONTH($A33,0)+1, All_Stats!$P:$P,"<>Email Marketing" ) -> 0 | H33: =SUMIFS(All_Stats!$K:$K, All_Stats!$D:$D,$B33, All_Stats!$B:$B,">="&EOMONTH($A33,-1)+1, All_Stats!$B:$B,"<"&EOMONTH($A33,0)+1, All_Stats!$P:$P,"<>Email Marketing" ) -> 0 | I33: =IFERROR(__xludf.DUMMYFUNCTION("COUNTUNIQUEIFS(All_Stats!A:A, All_Stats!$D:$D,$B33, All_Stats!$B:$B,"">=""&EOMONTH($A33,-1)+1, All_Stats!$B:$B,""<""&EOMONTH($A33,0)+1, All_Stats!$P:$P,""<>Email Marketing"" )"),0.0) -> 0
A34: 44317 | B34: V3 | C34: =if(ifna(VLOOKUP(B34,'Vendor Directory'!A:C,3,0),"NOT FOUND")="","NOT FOUND",VLOOKUP(B34,'Vendor Directory'!A:C,3,0)) -> #N/A | D34: =SUMIFS(All_Stats!$G:$G, All_Stats!$D:$D,$B34, All_Stats!$B:$B,">="&EOMONTH($A34,-1)+1, All_Stats!$B:$B,"<"&EOMONTH($A34,0)+1, All_Stats!$P:$P,"<>Email Marketing" ) -> 0 | E34: =SUMIFS(All_Stats!$I:$I, All_Stats!$D:$D,$B34, All_Stats!$B:$B,">="&EOMONTH($A34,-1)+1, All_Stats!$B:$B,"<"&EOMONTH($A34,0)+1, All_Stats!$P:$P,"<>Email Marketing" ) -> 0 | F34: =iferror(E34/D34,"N/A") -> N/A | G34: =SUMIFS(All_Stats!$H:$H, All_Stats!$D:$D,$B34, All_Stats!$B:$B,">="&EOMONTH($A34,-1)+1, All_Stats!$B:$B,"<"&EOMONTH($A34,0)+1, All_Stats!$P:$P,"<>Email Marketing" ) -> 0 | H34: =SUMIFS(All_Stats!$K:$K, All_Stats!$D:$D,$B34, All_Stats!$B:$B,">="&EOMONTH($A34,-1)+1, All_Stats!$B:$B,"<"&EOMONTH($A34,0)+1, All_Stats!$P:$P,"<>Email Marketing" ) -> 0 | I34: =IFERROR(__xludf.DUMMYFUNCTION("COUNTUNIQUEIFS(All_Stats!A:A, All_Stats!$D:$D,$B34, All_Stats!$B:$B,"">=""&EOMONTH($A34,-1)+1, All_Stats!$B:$B,""<""&EOMONTH($A34,0)+1, All_Stats!$P:$P,""<>Email Marketing"" )"),0.0) -> 0
A35: 44317 | B35: V4 | C35: =if(ifna(VLOOKUP(B35,'Vendor Directory'!A:C,3,0),"NOT FOUND")="","NOT FOUND",VLOOKUP(B35,'Vendor Directory'!A:C,3,0)) -> Vendor 2 Name | D35: =SUMIFS(All_Stats!$G:$G, All_Stats!$D:$D,$B35, All_Stats!$B:$B,">="&EOMONTH($A35,-1)+1, All_Stats!$B:$B,"<"&EOMONTH($A35,0)+1, All_Stats!$P:$P,"<>Email Marketing" ) -> 0 | E35: =SUMIFS(All_Stats!$I:$I, All_Stats!$D:$D,$B35, All_Stats!$B:$B,">="&EOMONTH($A35,-1)+1, All_Stats!$B:$B,"<"&EOMONTH($A35,0)+1, All_Stats!$P:$P,"<>Email Marketing" ) -> 0 | F35: =iferror(E35/D35,"N/A") -> N/A | G35: =SUMIFS(All_Stats!$H:$H, All_Stats!$D:$D,$B35, All_Stats!$B:$B,">="&EOMONTH($A35,-1)+1, All_Stats!$B:$B,"<"&EOMONTH($A35,0)+1, All_Stats!$P:$P,"<>Email Marketing" ) -> 0 | H35: =SUMIFS(All_Stats!$K:$K, All_Stats!$D:$D,$B35, All_Stats!$B:$B,">="&EOMONTH($A35,-1)+1, All_Stats!$B:$B,"<"&EOMONTH($A35,0)+1, All_Stats!$P:$P,"<>Email Marketing" ) -> 0 | I35: =IFERROR(__xludf.DUMMYFUNCTION("COUNTUNIQUEIFS(All_Stats!A:A, All_Stats!$D:$D,$B35, All_Stats!$B:$B,"">=""&EOMONTH($A35,-1)+1, All_Stats!$B:$B,""<""&EOMONTH($A35,0)+1, All_Stats!$P:$P,""<>Email Marketing"" )"),0.0) -> 0
A36: 44317 | B36: V5 | C36: =if(ifna(VLOOKUP(B36,'Vendor Directory'!A:C,3,0),"NOT FOUND")="","NOT FOUND",VLOOKUP(B36,'Vendor Directory'!A:C,3,0)) -> #N/A | D36: =SUMIFS(All_Stats!$G:$G, All_Stats!$D:$D,$B36, All_Stats!$B:$B,">="&EOMONTH($A36,-1)+1, All_Stats!$B:$B,"<"&EOMONTH($A36,0)+1, All_Stats!$P:$P,"<>Email Marketing" ) -> 0 | E36: =SUMIFS(All_Stats!$I:$I, All_Stats!$D:$D,$B36, All_Stats!$B:$B,">="&EOMONTH($A36,-1)+1, All_Stats!$B:$B,"<"&EOMONTH($A36,0)+1, All_Stats!$P:$P,"<>Email Marketing" ) -> 0 | F36: =iferror(E36/D36,"N/A") -> N/A | G36: =SUMIFS(All_Stats!$H:$H, All_Stats!$D:$D,$B36, All_Stats!$B:$B,">="&EOMONTH($A36,-1)+1, All_Stats!$B:$B,"<"&EOMONTH($A36,0)+1, All_Stats!$P:$P,"<>Email Marketing" ) -> 0 | H36: =SUMIFS(All_Stats!$K:$K, All_Stats!$D:$D,$B36, All_Stats!$B:$B,">="&EOMONTH($A36,-1)+1, All_Stats!$B:$B,"<"&EOMONTH($A36,0)+1, All_Stats!$P:$P,"<>Email Marketing" ) -> 0 | I36: =IFERROR(__xludf.DUMMYFUNCTION("COUNTUNIQUEIFS(All_Stats!A:A, All_Stats!$D:$D,$B36, All_Stats!$B:$B,"">=""&EOMONTH($A36,-1)+1, All_Stats!$B:$B,""<""&EOMONTH($A36,0)+1, All_Stats!$P:$P,""<>Email Marketing"" )"),0.0) -> 0
A37: 44317 | B37: V6 | C37: =if(ifna(VLOOKUP(B37,'Vendor Directory'!A:C,3,0),"NOT FOUND")="","NOT FOUND",VLOOKUP(B37,'Vendor Directory'!A:C,3,0)) -> #N/A | D37: =SUMIFS(All_Stats!$G:$G, All_Stats!$D:$D,$B37, All_Stats!$B:$B,">="&EOMONTH($A37,-1)+1, All_Stats!$B:$B,"<"&EOMONTH($A37,0)+1, All_Stats!$P:$P,"<>Email Marketing" ) -> 0 | E37: =SUMIFS(All_Stats!$I:$I, All_Stats!$D:$D,$B37, All_Stats!$B:$B,">="&EOMONTH($A37,-1)+1, All_Stats!$B:$B,"<"&EOMONTH($A37,0)+1, All_Stats!$P:$P,"<>Email Marketing" ) -> 0 | F37: =iferror(E37/D37,"N/A") -> N/A | G37: =SUMIFS(All_Stats!$H:$H, All_Stats!$D:$D,$B37, All_Stats!$B:$B,">="&EOMONTH($A37,-1)+1, All_Stats!$B:$B,"<"&EOMONTH($A37,0)+1, All_Stats!$P:$P,"<>Email Marketing" ) -> 0 | H37: =SUMIFS(All_Stats!$K:$K, All_Stats!$D:$D,$B37, All_Stats!$B:$B,">="&EOMONTH($A37,-1)+1, All_Stats!$B:$B,"<"&EOMONTH($A37,0)+1, All_Stats!$P:$P,"<>Email Marketing" ) -> 0 | I37: =IFERROR(__xludf.DUMMYFUNCTION("COUNTUNIQUEIFS(All_Stats!A:A, All_Stats!$D:$D,$B37, All_Stats!$B:$B,"">=""&EOMONTH($A37,-1)+1, All_Stats!$B:$B,""<""&EOMONTH($A37,0)+1, All_Stats!$P:$P,""<>Email Marketing"" )"),0.0) -> 0
A38: 44317 | B38: V9 | C38: =if(ifna(VLOOKUP(B38,'Vendor Directory'!A:C,3,0),"NOT FOUND")="","NOT FOUND",VLOOKUP(B38,'Vendor Directory'!A:C,3,0)) -> Vendor 3 Name | D38: =SUMIFS(All_Stats!$G:$G, All_Stats!$D:$D,$B38, All_Stats!$B:$B,">="&EOMONTH($A38,-1)+1, All_Stats!$B:$B,"<"&EOMONTH($A38,0)+1, All_Stats!$P:$P,"<>Email Marketing" ) -> 0 | E38: =SUMIFS(All_Stats!$I:$I, All_Stats!$D:$D,$B38, All_Stats!$B:$B,">="&EOMONTH($A38,-1)+1, All_Stats!$B:$B,"<"&EOMONTH($A38,0)+1, All_Stats!$P:$P,"<>Email Marketing" ) -> 0 | F38: =iferror(E38/D38,"N/A") -> N/A | G38: =SUMIFS(All_Stats!$H:$H, All_Stats!$D:$D,$B38, All_Stats!$B:$B,">="&EOMONTH($A38,-1)+1, All_Stats!$B:$B,"<"&EOMONTH($A38,0)+1, All_Stats!$P:$P,"<>Email Marketing" ) -> 0 | H38: =SUMIFS(All_Stats!$K:$K, All_Stats!$D:$D,$B38, All_Stats!$B:$B,">="&EOMONTH($A38,-1)+1, All_Stats!$B:$B,"<"&EOMONTH($A38,0)+1, All_Stats!$P:$P,"<>Email Marketing" ) -> 0 | I38: =IFERROR(__xludf.DUMMYFUNCTION("COUNTUNIQUEIFS(All_Stats!A:A, All_Stats!$D:$D,$B38, All_Stats!$B:$B,"">=""&EOMONTH($A38,-1)+1, All_Stats!$B:$B,""<""&EOMONTH($A38,0)+1, All_Stats!$P:$P,""<>Email Marketing"" )"),0.0) -> 0
A39: 44317 | B39: V10 | C39: =if(ifna(VLOOKUP(B39,'Vendor Directory'!A:C,3,0),"NOT FOUND")="","NOT FOUND",VLOOKUP(B39,'Vendor Directory'!A:C,3,0)) -> Vendor 4 Name | D39: =SUMIFS(All_Stats!$G:$G, All_Stats!$D:$D,$B39, All_Stats!$B:$B,">="&EOMONTH($A39,-1)+1, All_Stats!$B:$B,"<"&EOMONTH($A39,0)+1, All_Stats!$P:$P,"<>Email Marketing" ) -> 0 | E39: =SUMIFS(All_Stats!$I:$I, All_Stats!$D:$D,$B39, All_Stats!$B:$B,">="&EOMONTH($A39,-1)+1, All_Stats!$B:$B,"<"&EOMONTH($A39,0)+1, All_Stats!$P:$P,"<>Email Marketing" ) -> 0 | F39: =iferror(E39/D39,"N/A") -> N/A | G39: =SUMIFS(All_Stats!$H:$H, All_Stats!$D:$D,$B39, All_Stats!$B:$B,">="&EOMONTH($A39,-1)+1, All_Stats!$B:$B,"<"&EOMONTH($A39,0)+1, All_Stats!$P:$P,"<>Email Marketing" ) -> 0 | H39: =SUMIFS(All_Stats!$K:$K, All_Stats!$D:$D,$B39, All_Stats!$B:$B,">="&EOMONTH($A39,-1)+1, All_Stats!$B:$B,"<"&EOMONTH($A39,0)+1, All_Stats!$P:$P,"<>Email Marketing" ) -> 0 | I39: =IFERROR(__xludf.DUMMYFUNCTION("COUNTUNIQUEIFS(All_Stats!A:A, All_Stats!$D:$D,$B39, All_Stats!$B:$B,"">=""&EOMONTH($A39,-1)+1, All_Stats!$B:$B,""<""&EOMONTH($A39,0)+1, All_Stats!$P:$P,""<>Email Marketing"" )"),0.0) -> 0
